[2025-04-13 04:45:41] [INFO] 172.31.128.25 - - [13/Apr/2025 04:45:41] "GET /static/js/changelog.js HTTP/1.1" 304 -
[2025-04-13 04:45:41] [INFO] 172.31.128.25 - - [13/Apr/2025 04:45:41] "GET /static/js/main.js HTTP/1.1" 304 -
[2025-04-13 04:45:41] [INFO] 172.31.128.25 - - [13/Apr/2025 04:45:41] "GET /static/images/logo-rounded.png HTTP/1.1" 304 -
[2025-04-13 04:45:41] [INFO] 172.31.128.25 - - [13/Apr/2025 04:45:41] "GET /api/changelog HTTP/1.1" 200 -
[2025-04-13 04:45:41] [INFO] 172.31.128.25 - - [13/Apr/2025 04:45:41] "GET /static/images/favicon.ico HTTP/1.1" 304 -
[2025-04-13 04:45:41] [INFO] 172.31.128.25 - - [13/Apr/2025 04:45:41] "GET /api/clubs/28/posts HTTP/1.1" 200 -
[2025-04-13 04:45:46] [INFO] 172.31.128.25 - - [13/Apr/2025 04:45:46] "DELETE /api/clubs/28/posts/6 HTTP/1.1" 200 -
[2025-04-13 04:45:51,539] [ERROR] Unhandled Exception: {'error_type': 'Database Error', 'error_message': '(psycopg2.errors.NotNullViolation) null value in column "post_id" of relation "club_post_like" violates not-null constraint\nDETAIL:  Failing row contains (2, null, 149, 2025-04-13 03:58:11.404953).\n\n[SQL: UPDATE club_post_like SET post_id=%(post_id)s WHERE club_post_like.id = %(club_post_like_id)s]\n[parameters: {\'post_id\': None, \'club_post_like_id\': 2}]\n(Background on this error at: https://sqlalche.me/e/20/gkpj)', 'error_details': None, 'file_name': None, 'line_number': None, 'code_snippet': None, 'traceback': '  File "/home/runner/workspace/.pythonlibs/lib/python3.11/site-packages/flask/app.py", line 867, in full_dispatch_request\n    rv = self.dispatch_request()\n         ^^^^^^^^^^^^^^^^^^^^^^^\n  File "/home/runner/workspace/.pythonlibs/lib/python3.11/site-packages/flask/app.py", line 852, in dispatch_request\n    return self.ensure_sync(self.view_functions[rule.endpoint])(**view_args)\n           ^^^^^^^^^^^^^^^^^^^^^^^^^^^^^^^^^^^^^^^^^^^^^^^^^^^^^^^^^^^^^^^^^\n  File "/home/runner/workspace/.pythonlibs/lib/python3.11/site-packages/flask_login/utils.py", line 290, in decorated_view\n    return current_app.ensure_sync(func)(*args, **kwargs)\n           ^^^^^^^^^^^^^^^^^^^^^^^^^^^^^^^^^^^^^^^^^^^^^^\n  File "/home/runner/workspace/app.py", line 3813, in manage_club_post\n    db.session.commit()\n  File "/home/runner/workspace/.pythonlibs/lib/python3.11/site-packages/sqlalchemy/orm/scoping.py", line 599, in commit\n    return self._proxied.commit()\n           ^^^^^^^^^^^^^^^^^^^^^^\n  File "/home/runner/workspace/.pythonlibs/lib/python3.11/site-packages/sqlalchemy/orm/session.py", line 2032, in commit\n    trans.commit(_to_root=True)\n  File "<string>", line 2, in commit\n  File "/home/runner/workspace/.pythonlibs/lib/python3.11/site-packages/sqlalchemy/orm/state_changes.py", line 139, in _go\n    ret_value = fn(self, *arg, **kw)\n                ^^^^^^^^^^^^^^^^^^^^\n  File "/home/runner/workspace/.pythonlibs/lib/python3.11/site-packages/sqlalchemy/orm/session.py", line 1313, in commit\n    self._prepare_impl()\n  File "<string>", line 2, in _prepare_impl\n  File "/home/runner/workspace/.pythonlibs/lib/python3.11/site-packages/sqlalchemy/orm/state_changes.py", line 139, in _go\n    ret_value = fn(self, *arg, **kw)\n                ^^^^^^^^^^^^^^^^^^^^\n  File "/home/runner/workspace/.pythonlibs/lib/python3.11/site-packages/sqlalchemy/orm/session.py", line 1288, in _prepare_impl\n    self.session.flush()\n  File "/home/runner/workspace/.pythonlibs/lib/python3.11/site-packages/sqlalchemy/orm/session.py", line 4353, in flush\n    self._flush(objects)\n  File "/home/runner/workspace/.pythonlibs/lib/python3.11/site-packages/sqlalchemy/orm/session.py", line 4488, in _flush\n    with util.safe_reraise():\n  File "/home/runner/workspace/.pythonlibs/lib/python3.11/site-packages/sqlalchemy/util/langhelpers.py", line 146, in __exit__\n    raise exc_value.with_traceback(exc_tb)\n  File "/home/runner/workspace/.pythonlibs/lib/python3.11/site-packages/sqlalchemy/orm/session.py", line 4449, in _flush\n    flush_context.execute()\n  File "/home/runner/workspace/.pythonlibs/lib/python3.11/site-packages/sqlalchemy/orm/unitofwork.py", line 466, in execute\n    rec.execute(self)\n  File "/home/runner/workspace/.pythonlibs/lib/python3.11/site-packages/sqlalchemy/orm/unitofwork.py", line 642, in execute\n    util.preloaded.orm_persistence.save_obj(\n  File "/home/runner/workspace/.pythonlibs/lib/python3.11/site-packages/sqlalchemy/orm/persistence.py", line 85, in save_obj\n    _emit_update_statements(\n  File "/home/runner/workspace/.pythonlibs/lib/python3.11/site-packages/sqlalchemy/orm/persistence.py", line 912, in _emit_update_statements\n    c = connection.execute(\n        ^^^^^^^^^^^^^^^^^^^\n  File "/home/runner/workspace/.pythonlibs/lib/python3.11/site-packages/sqlalchemy/engine/base.py", line 1416, in execute\n    return meth(\n           ^^^^^\n  File "/home/runner/workspace/.pythonlibs/lib/python3.11/site-packages/sqlalchemy/sql/elements.py", line 523, in _execute_on_connection\n    return connection._execute_clauseelement(\n           ^^^^^^^^^^^^^^^^^^^^^^^^^^^^^^^^^^\n  File "/home/runner/workspace/.pythonlibs/lib/python3.11/site-packages/sqlalchemy/engine/base.py", line 1638, in _execute_clauseelement\n    ret = self._execute_context(\n          ^^^^^^^^^^^^^^^^^^^^^^\n  File "/home/runner/workspace/.pythonlibs/lib/python3.11/site-packages/sqlalchemy/engine/base.py", line 1843, in _execute_context\n    return self._exec_single_context(\n           ^^^^^^^^^^^^^^^^^^^^^^^^^^\n  File "/home/runner/workspace/.pythonlibs/lib/python3.11/site-packages/sqlalchemy/engine/base.py", line 1983, in _exec_single_context\n    self._handle_dbapi_exception(\n  File "/home/runner/workspace/.pythonlibs/lib/python3.11/site-packages/sqlalchemy/engine/base.py", line 2352, in _handle_dbapi_exception\n    raise sqlalchemy_exception.with_traceback(exc_info[2]) from e\n  File "/home/runner/workspace/.pythonlibs/lib/python3.11/site-packages/sqlalchemy/engine/base.py", line 1964, in _exec_single_context\n    self.dialect.do_execute(\n  File "/home/runner/workspace/.pythonlibs/lib/python3.11/site-packages/sqlalchemy/engine/default.py", line 945, in do_execute\n    cursor.execute(statement, parameters)\n', 'suggestions': ['Verify database connection settings', 'Check for invalid queries or constraints', 'Ensure all required fields are provided']}
[2025-04-13 04:45:51] [ERROR] Unhandled Exception: {'error_type': 'Database Error', 'error_message': '(psycopg2.errors.NotNullViolation) null value in column "post_id" of relation "club_post_like" violates not-null constraint\nDETAIL:  Failing row contains (2, null, 149, 2025-04-13 03:58:11.404953).\n\n[SQL: UPDATE club_post_like SET post_id=%(post_id)s WHERE club_post_like.id = %(club_post_like_id)s]\n[parameters: {\'post_id\': None, \'club_post_like_id\': 2}]\n(Background on this error at: https://sqlalche.me/e/20/gkpj)', 'error_details': None, 'file_name': None, 'line_number': None, 'code_snippet': None, 'traceback': '  File "/home/runner/workspace/.pythonlibs/lib/python3.11/site-packages/flask/app.py", line 867, in full_dispatch_request\n    rv = self.dispatch_request()\n         ^^^^^^^^^^^^^^^^^^^^^^^\n  File "/home/runner/workspace/.pythonlibs/lib/python3.11/site-packages/flask/app.py", line 852, in dispatch_request\n    return self.ensure_sync(self.view_functions[rule.endpoint])(**view_args)\n           ^^^^^^^^^^^^^^^^^^^^^^^^^^^^^^^^^^^^^^^^^^^^^^^^^^^^^^^^^^^^^^^^^\n  File "/home/runner/workspace/.pythonlibs/lib/python3.11/site-packages/flask_login/utils.py", line 290, in decorated_view\n    return current_app.ensure_sync(func)(*args, **kwargs)\n           ^^^^^^^^^^^^^^^^^^^^^^^^^^^^^^^^^^^^^^^^^^^^^^\n  File "/home/runner/workspace/app.py", line 3813, in manage_club_post\n    db.session.commit()\n  File "/home/runner/workspace/.pythonlibs/lib/python3.11/site-packages/sqlalchemy/orm/scoping.py", line 599, in commit\n    return self._proxied.commit()\n           ^^^^^^^^^^^^^^^^^^^^^^\n  File "/home/runner/workspace/.pythonlibs/lib/python3.11/site-packages/sqlalchemy/orm/session.py", line 2032, in commit\n    trans.commit(_to_root=True)\n  File "<string>", line 2, in commit\n  File "/home/runner/workspace/.pythonlibs/lib/python3.11/site-packages/sqlalchemy/orm/state_changes.py", line 139, in _go\n    ret_value = fn(self, *arg, **kw)\n                ^^^^^^^^^^^^^^^^^^^^\n  File "/home/runner/workspace/.pythonlibs/lib/python3.11/site-packages/sqlalchemy/orm/session.py", line 1313, in commit\n    self._prepare_impl()\n  File "<string>", line 2, in _prepare_impl\n  File "/home/runner/workspace/.pythonlibs/lib/python3.11/site-packages/sqlalchemy/orm/state_changes.py", line 139, in _go\n    ret_value = fn(self, *arg, **kw)\n                ^^^^^^^^^^^^^^^^^^^^\n  File "/home/runner/workspace/.pythonlibs/lib/python3.11/site-packages/sqlalchemy/orm/session.py", line 1288, in _prepare_impl\n    self.session.flush()\n  File "/home/runner/workspace/.pythonlibs/lib/python3.11/site-packages/sqlalchemy/orm/session.py", line 4353, in flush\n    self._flush(objects)\n  File "/home/runner/workspace/.pythonlibs/lib/python3.11/site-packages/sqlalchemy/orm/session.py", line 4488, in _flush\n    with util.safe_reraise():\n  File "/home/runner/workspace/.pythonlibs/lib/python3.11/site-packages/sqlalchemy/util/langhelpers.py", line 146, in __exit__\n    raise exc_value.with_traceback(exc_tb)\n  File "/home/runner/workspace/.pythonlibs/lib/python3.11/site-packages/sqlalchemy/orm/session.py", line 4449, in _flush\n    flush_context.execute()\n  File "/home/runner/workspace/.pythonlibs/lib/python3.11/site-packages/sqlalchemy/orm/unitofwork.py", line 466, in execute\n    rec.execute(self)\n  File "/home/runner/workspace/.pythonlibs/lib/python3.11/site-packages/sqlalchemy/orm/unitofwork.py", line 642, in execute\n    util.preloaded.orm_persistence.save_obj(\n  File "/home/runner/workspace/.pythonlibs/lib/python3.11/site-packages/sqlalchemy/orm/persistence.py", line 85, in save_obj\n    _emit_update_statements(\n  File "/home/runner/workspace/.pythonlibs/lib/python3.11/site-packages/sqlalchemy/orm/persistence.py", line 912, in _emit_update_statements\n    c = connection.execute(\n        ^^^^^^^^^^^^^^^^^^^\n  File "/home/runner/workspace/.pythonlibs/lib/python3.11/site-packages/sqlalchemy/engine/base.py", line 1416, in execute\n    return meth(\n           ^^^^^\n  File "/home/runner/workspace/.pythonlibs/lib/python3.11/site-packages/sqlalchemy/sql/elements.py", line 523, in _execute_on_connection\n    return connection._execute_clauseelement(\n           ^^^^^^^^^^^^^^^^^^^^^^^^^^^^^^^^^^\n  File "/home/runner/workspace/.pythonlibs/lib/python3.11/site-packages/sqlalchemy/engine/base.py", line 1638, in _execute_clauseelement\n    ret = self._execute_context(\n          ^^^^^^^^^^^^^^^^^^^^^^\n  File "/home/runner/workspace/.pythonlibs/lib/python3.11/site-packages/sqlalchemy/engine/base.py", line 1843, in _execute_context\n    return self._exec_single_context(\n           ^^^^^^^^^^^^^^^^^^^^^^^^^^\n  File "/home/runner/workspace/.pythonlibs/lib/python3.11/site-packages/sqlalchemy/engine/base.py", line 1983, in _exec_single_context\n    self._handle_dbapi_exception(\n  File "/home/runner/workspace/.pythonlibs/lib/python3.11/site-packages/sqlalchemy/engine/base.py", line 2352, in _handle_dbapi_exception\n    raise sqlalchemy_exception.with_traceback(exc_info[2]) from e\n  File "/home/runner/workspace/.pythonlibs/lib/python3.11/site-packages/sqlalchemy/engine/base.py", line 1964, in _exec_single_context\n    self.dialect.do_execute(\n  File "/home/runner/workspace/.pythonlibs/lib/python3.11/site-packages/sqlalchemy/engine/default.py", line 945, in do_execute\n    cursor.execute(statement, parameters)\n', 'suggestions': ['Verify database connection settings', 'Check for invalid queries or constraints', 'Ensure all required fields are provided']}
[2025-04-13 04:45:51] [INFO] 172.31.128.25 - - [13/Apr/2025 04:45:51] "DELETE /api/clubs/28/posts/5 HTTP/1.1" 500 -
Traceback (most recent call last):
  File "/home/runner/workspace/.pythonlibs/lib/python3.11/site-packages/sqlalchemy/engine/base.py", line 1964, in _exec_single_context
    self.dialect.do_execute(
  File "/home/runner/workspace/.pythonlibs/lib/python3.11/site-packages/sqlalchemy/engine/default.py", line 945, in do_execute
    cursor.execute(statement, parameters)
psycopg2.errors.NotNullViolation: null value in column "post_id" of relation "club_post_like" violates not-null constraint
DETAIL:  Failing row contains (2, null, 149, 2025-04-13 03:58:11.404953).


The above exception was the direct cause of the following exception:

Traceback (most recent call last):
  File "/home/runner/workspace/.pythonlibs/lib/python3.11/site-packages/flask/app.py", line 867, in full_dispatch_request
    rv = self.dispatch_request()
         ^^^^^^^^^^^^^^^^^^^^^^^
  File "/home/runner/workspace/.pythonlibs/lib/python3.11/site-packages/flask/app.py", line 852, in dispatch_request
    return self.ensure_sync(self.view_functions[rule.endpoint])(**view_args)
           ^^^^^^^^^^^^^^^^^^^^^^^^^^^^^^^^^^^^^^^^^^^^^^^^^^^^^^^^^^^^^^^^^
  File "/home/runner/workspace/.pythonlibs/lib/python3.11/site-packages/flask_login/utils.py", line 290, in decorated_view
    return current_app.ensure_sync(func)(*args, **kwargs)
           ^^^^^^^^^^^^^^^^^^^^^^^^^^^^^^^^^^^^^^^^^^^^^^
  File "/home/runner/workspace/app.py", line 3813, in manage_club_post
    db.session.commit()
  File "/home/runner/workspace/.pythonlibs/lib/python3.11/site-packages/sqlalchemy/orm/scoping.py", line 599, in commit
    return self._proxied.commit()
           ^^^^^^^^^^^^^^^^^^^^^^
  File "/home/runner/workspace/.pythonlibs/lib/python3.11/site-packages/sqlalchemy/orm/session.py", line 2032, in commit
    trans.commit(_to_root=True)
  File "<string>", line 2, in commit
  File "/home/runner/workspace/.pythonlibs/lib/python3.11/site-packages/sqlalchemy/orm/state_changes.py", line 139, in _go
    ret_value = fn(self, *arg, **kw)
                ^^^^^^^^^^^^^^^^^^^^
  File "/home/runner/workspace/.pythonlibs/lib/python3.11/site-packages/sqlalchemy/orm/session.py", line 1313, in commit
    self._prepare_impl()
  File "<string>", line 2, in _prepare_impl
  File "/home/runner/workspace/.pythonlibs/lib/python3.11/site-packages/sqlalchemy/orm/state_changes.py", line 139, in _go
    ret_value = fn(self, *arg, **kw)
                ^^^^^^^^^^^^^^^^^^^^
  File "/home/runner/workspace/.pythonlibs/lib/python3.11/site-packages/sqlalchemy/orm/session.py", line 1288, in _prepare_impl
    self.session.flush()
  File "/home/runner/workspace/.pythonlibs/lib/python3.11/site-packages/sqlalchemy/orm/session.py", line 4353, in flush
    self._flush(objects)
  File "/home/runner/workspace/.pythonlibs/lib/python3.11/site-packages/sqlalchemy/orm/session.py", line 4488, in _flush
    with util.safe_reraise():
  File "/home/runner/workspace/.pythonlibs/lib/python3.11/site-packages/sqlalchemy/util/langhelpers.py", line 146, in __exit__
    raise exc_value.with_traceback(exc_tb)
  File "/home/runner/workspace/.pythonlibs/lib/python3.11/site-packages/sqlalchemy/orm/session.py", line 4449, in _flush
    flush_context.execute()
  File "/home/runner/workspace/.pythonlibs/lib/python3.11/site-packages/sqlalchemy/orm/unitofwork.py", line 466, in execute
    rec.execute(self)
  File "/home/runner/workspace/.pythonlibs/lib/python3.11/site-packages/sqlalchemy/orm/unitofwork.py", line 642, in execute
    util.preloaded.orm_persistence.save_obj(
  File "/home/runner/workspace/.pythonlibs/lib/python3.11/site-packages/sqlalchemy/orm/persistence.py", line 85, in save_obj
    _emit_update_statements(
  File "/home/runner/workspace/.pythonlibs/lib/python3.11/site-packages/sqlalchemy/orm/persistence.py", line 912, in _emit_update_statements
    c = connection.execute(
        ^^^^^^^^^^^^^^^^^^^
  File "/home/runner/workspace/.pythonlibs/lib/python3.11/site-packages/sqlalchemy/engine/base.py", line 1416, in execute
    return meth(
           ^^^^^
  File "/home/runner/workspace/.pythonlibs/lib/python3.11/site-packages/sqlalchemy/sql/elements.py", line 523, in _execute_on_connection
    return connection._execute_clauseelement(
           ^^^^^^^^^^^^^^^^^^^^^^^^^^^^^^^^^^
  File "/home/runner/workspace/.pythonlibs/lib/python3.11/site-packages/sqlalchemy/engine/base.py", line 1638, in _execute_clauseelement
    ret = self._execute_context(
          ^^^^^^^^^^^^^^^^^^^^^^
  File "/home/runner/workspace/.pythonlibs/lib/python3.11/site-packages/sqlalchemy/engine/base.py", line 1843, in _execute_context
    return self._exec_single_context(
           ^^^^^^^^^^^^^^^^^^^^^^^^^^
  File "/home/runner/workspace/.pythonlibs/lib/python3.11/site-packages/sqlalchemy/engine/base.py", line 1983, in _exec_single_context
    self._handle_dbapi_exception(
  File "/home/runner/workspace/.pythonlibs/lib/python3.11/site-packages/sqlalchemy/engine/base.py", line 2352, in _handle_dbapi_exception
    raise sqlalchemy_exception.with_traceback(exc_info[2]) from e
  File "/home/runner/workspace/.pythonlibs/lib/python3.11/site-packages/sqlalchemy/engine/base.py", line 1964, in _exec_single_context
    self.dialect.do_execute(
  File "/home/runner/workspace/.pythonlibs/lib/python3.11/site-packages/sqlalchemy/engine/default.py", line 945, in do_execute
    cursor.execute(statement, parameters)
sqlalchemy.exc.IntegrityError: (psycopg2.errors.NotNullViolation) null value in column "post_id" of relation "club_post_like" violates not-null constraint
DETAIL:  Failing row contains (2, null, 149, 2025-04-13 03:58:11.404953).

[SQL: UPDATE club_post_like SET post_id=%(post_id)s WHERE club_post_like.id = %(club_post_like_id)s]
[parameters: {'post_id': None, 'club_post_like_id': 2}]
(Background on this error at: https://sqlalche.me/e/20/gkpj)

During handling of the above exception, another exception occurred:

Traceback (most recent call last):
  File "/home/runner/workspace/.pythonlibs/lib/python3.11/site-packages/flask/app.py", line 1478, in __call__
    return self.wsgi_app(environ, start_response)
           ^^^^^^^^^^^^^^^^^^^^^^^^^^^^^^^^^^^^^^
  File "/home/runner/workspace/.pythonlibs/lib/python3.11/site-packages/flask/app.py", line 1458, in wsgi_app
    response = self.handle_exception(e)
               ^^^^^^^^^^^^^^^^^^^^^^^^
  File "/home/runner/workspace/.pythonlibs/lib/python3.11/site-packages/flask/app.py", line 1455, in wsgi_app
    response = self.full_dispatch_request()
               ^^^^^^^^^^^^^^^^^^^^^^^^^^^^
  File "/home/runner/workspace/.pythonlibs/lib/python3.11/site-packages/flask/app.py", line 869, in full_dispatch_request
    rv = self.handle_user_exception(e)
         ^^^^^^^^^^^^^^^^^^^^^^^^^^^^^
  File "/home/runner/workspace/.pythonlibs/lib/python3.11/site-packages/flask/app.py", line 759, in handle_user_exception
    return self.ensure_sync(handler)(e)
           ^^^^^^^^^^^^^^^^^^^^^^^^^^^^
  File "/home/runner/workspace/app.py", line 193, in handle_error
    return render_template('errors/generic.html', **context), code
           ^^^^^^^^^^^^^^^^^^^^^^^^^^^^^^^^^^^^^^^^^^^^^^^^^^^^^^^
  File "/home/runner/workspace/.pythonlibs/lib/python3.11/site-packages/flask/templating.py", line 152, in render_template
    return _render(app, template, context)
           ^^^^^^^^^^^^^^^^^^^^^^^^^^^^^^^
  File "/home/runner/workspace/.pythonlibs/lib/python3.11/site-packages/flask/templating.py", line 133, in _render
    rv = template.render(context)
         ^^^^^^^^^^^^^^^^^^^^^^^^
  File "/home/runner/workspace/.pythonlibs/lib/python3.11/site-packages/jinja2/environment.py", line 1295, in render
    self.environment.handle_exception()
  File "/home/runner/workspace/.pythonlibs/lib/python3.11/site-packages/jinja2/environment.py", line 942, in handle_exception
    raise rewrite_traceback_stack(source=source)
  File "/home/runner/workspace/templates/errors/generic.html", line 1, in top-level template code
    {% extends "errors/base_error.html" %}
  File "/home/runner/workspace/templates/errors/base_error.html", line 1, in top-level template code
    {% extends "base.html" %}
  File "/home/runner/workspace/templates/base.html", line 33, in top-level template code
    {% if current_user.is_authenticated %}
  File "/home/runner/workspace/.pythonlibs/lib/python3.11/site-packages/jinja2/environment.py", line 490, in getattr
    return getattr(obj, attribute)
           ^^^^^^^^^^^^^^^^^^^^^^^
  File "/home/runner/workspace/.pythonlibs/lib/python3.11/site-packages/flask_login/mixins.py", line 17, in is_authenticated
    return self.is_active
           ^^^^^^^^^^^^^^
  File "/home/runner/workspace/.pythonlibs/lib/python3.11/site-packages/sqlalchemy/orm/attributes.py", line 566, in __get__
    return self.impl.get(state, dict_)  # type: ignore[no-any-return]
           ^^^^^^^^^^^^^^^^^^^^^^^^^^^^^^^^^^^^^^^^^^^^^^^^^^^^^^^^^^
  File "/home/runner/workspace/.pythonlibs/lib/python3.11/site-packages/sqlalchemy/orm/attributes.py", line 1086, in get
    value = self._fire_loader_callables(state, key, passive)
            ^^^^^^^^^^^^^^^^^^^^^^^^^^^^^^^^^^^^^^^^^^^^^^^^
  File "/home/runner/workspace/.pythonlibs/lib/python3.11/site-packages/sqlalchemy/orm/attributes.py", line 1116, in _fire_loader_callables
    return state._load_expired(state, passive)
           ^^^^^^^^^^^^^^^^^^^^^^^^^^^^^^^^^^^
  File "/home/runner/workspace/.pythonlibs/lib/python3.11/site-packages/sqlalchemy/orm/state.py", line 803, in _load_expired
    self.manager.expired_attribute_loader(self, toload, passive)
  File "/home/runner/workspace/.pythonlibs/lib/python3.11/site-packages/sqlalchemy/orm/loading.py", line 1670, in load_scalar_attributes
    result = load_on_ident(
             ^^^^^^^^^^^^^^
  File "/home/runner/workspace/.pythonlibs/lib/python3.11/site-packages/sqlalchemy/orm/loading.py", line 509, in load_on_ident
    return load_on_pk_identity(
           ^^^^^^^^^^^^^^^^^^^^
  File "/home/runner/workspace/.pythonlibs/lib/python3.11/site-packages/sqlalchemy/orm/loading.py", line 694, in load_on_pk_identity
    session.execute(
  File "/home/runner/workspace/.pythonlibs/lib/python3.11/site-packages/sqlalchemy/orm/session.py", line 2365, in execute
    return self._execute_internal(
           ^^^^^^^^^^^^^^^^^^^^^^^
  File "/home/runner/workspace/.pythonlibs/lib/python3.11/site-packages/sqlalchemy/orm/session.py", line 2241, in _execute_internal
    conn = self._connection_for_bind(bind)
           ^^^^^^^^^^^^^^^^^^^^^^^^^^^^^^^
  File "/home/runner/workspace/.pythonlibs/lib/python3.11/site-packages/sqlalchemy/orm/session.py", line 2110, in _connection_for_bind
    return trans._connection_for_bind(engine, execution_options)
           ^^^^^^^^^^^^^^^^^^^^^^^^^^^^^^^^^^^^^^^^^^^^^^^^^^^^^
  File "<string>", line 2, in _connection_for_bind
  File "/home/runner/workspace/.pythonlibs/lib/python3.11/site-packages/sqlalchemy/orm/state_changes.py", line 103, in _go
    self._raise_for_prerequisite_state(fn.__name__, current_state)
  File "/home/runner/workspace/.pythonlibs/lib/python3.11/site-packages/sqlalchemy/orm/session.py", line 973, in _raise_for_prerequisite_state
    raise sa_exc.PendingRollbackError(
sqlalchemy.exc.PendingRollbackError: This Session's transaction has been rolled back due to a previous exception during flush. To begin a new transaction with this Session, first issue Session.rollback(). Original exception was: (psycopg2.errors.NotNullViolation) null value in column "post_id" of relation "club_post_like" violates not-null constraint
DETAIL:  Failing row contains (2, null, 149, 2025-04-13 03:58:11.404953).

[SQL: UPDATE club_post_like SET post_id=%(post_id)s WHERE club_post_like.id = %(club_post_like_id)s]
[parameters: {'post_id': None, 'club_post_like_id': 2}]
(Background on this error at: https://sqlalche.me/e/20/gkpj) (Background on this error at: https://sqlalche.me/e/20/7s2a)
[2025-04-13 04:45:55,103] [ERROR] Unhandled Exception: {'error_type': 'Database Error', 'error_message': '(psycopg2.errors.NotNullViolation) null value in column "post_id" of relation "club_post_like" violates not-null constraint\nDETAIL:  Failing row contains (2, null, 149, 2025-04-13 03:58:11.404953).\n\n[SQL: UPDATE club_post_like SET post_id=%(post_id)s WHERE club_post_like.id = %(club_post_like_id)s]\n[parameters: {\'post_id\': None, \'club_post_like_id\': 2}]\n(Background on this error at: https://sqlalche.me/e/20/gkpj)', 'error_details': None, 'file_name': None, 'line_number': None, 'code_snippet': None, 'traceback': '  File "/home/runner/workspace/.pythonlibs/lib/python3.11/site-packages/flask/app.py", line 867, in full_dispatch_request\n    rv = self.dispatch_request()\n         ^^^^^^^^^^^^^^^^^^^^^^^\n  File "/home/runner/workspace/.pythonlibs/lib/python3.11/site-packages/flask/app.py", line 852, in dispatch_request\n    return self.ensure_sync(self.view_functions[rule.endpoint])(**view_args)\n           ^^^^^^^^^^^^^^^^^^^^^^^^^^^^^^^^^^^^^^^^^^^^^^^^^^^^^^^^^^^^^^^^^\n  File "/home/runner/workspace/.pythonlibs/lib/python3.11/site-packages/flask_login/utils.py", line 290, in decorated_view\n    return current_app.ensure_sync(func)(*args, **kwargs)\n           ^^^^^^^^^^^^^^^^^^^^^^^^^^^^^^^^^^^^^^^^^^^^^^\n  File "/home/runner/workspace/app.py", line 3813, in manage_club_post\n    db.session.commit()\n  File "/home/runner/workspace/.pythonlibs/lib/python3.11/site-packages/sqlalchemy/orm/scoping.py", line 599, in commit\n    return self._proxied.commit()\n           ^^^^^^^^^^^^^^^^^^^^^^\n  File "/home/runner/workspace/.pythonlibs/lib/python3.11/site-packages/sqlalchemy/orm/session.py", line 2032, in commit\n    trans.commit(_to_root=True)\n  File "<string>", line 2, in commit\n  File "/home/runner/workspace/.pythonlibs/lib/python3.11/site-packages/sqlalchemy/orm/state_changes.py", line 139, in _go\n    ret_value = fn(self, *arg, **kw)\n                ^^^^^^^^^^^^^^^^^^^^\n  File "/home/runner/workspace/.pythonlibs/lib/python3.11/site-packages/sqlalchemy/orm/session.py", line 1313, in commit\n    self._prepare_impl()\n  File "<string>", line 2, in _prepare_impl\n  File "/home/runner/workspace/.pythonlibs/lib/python3.11/site-packages/sqlalchemy/orm/state_changes.py", line 139, in _go\n    ret_value = fn(self, *arg, **kw)\n                ^^^^^^^^^^^^^^^^^^^^\n  File "/home/runner/workspace/.pythonlibs/lib/python3.11/site-packages/sqlalchemy/orm/session.py", line 1288, in _prepare_impl\n    self.session.flush()\n  File "/home/runner/workspace/.pythonlibs/lib/python3.11/site-packages/sqlalchemy/orm/session.py", line 4353, in flush\n    self._flush(objects)\n  File "/home/runner/workspace/.pythonlibs/lib/python3.11/site-packages/sqlalchemy/orm/session.py", line 4488, in _flush\n    with util.safe_reraise():\n  File "/home/runner/workspace/.pythonlibs/lib/python3.11/site-packages/sqlalchemy/util/langhelpers.py", line 146, in __exit__\n    raise exc_value.with_traceback(exc_tb)\n  File "/home/runner/workspace/.pythonlibs/lib/python3.11/site-packages/sqlalchemy/orm/session.py", line 4449, in _flush\n    flush_context.execute()\n  File "/home/runner/workspace/.pythonlibs/lib/python3.11/site-packages/sqlalchemy/orm/unitofwork.py", line 466, in execute\n    rec.execute(self)\n  File "/home/runner/workspace/.pythonlibs/lib/python3.11/site-packages/sqlalchemy/orm/unitofwork.py", line 642, in execute\n    util.preloaded.orm_persistence.save_obj(\n  File "/home/runner/workspace/.pythonlibs/lib/python3.11/site-packages/sqlalchemy/orm/persistence.py", line 85, in save_obj\n    _emit_update_statements(\n  File "/home/runner/workspace/.pythonlibs/lib/python3.11/site-packages/sqlalchemy/orm/persistence.py", line 912, in _emit_update_statements\n    c = connection.execute(\n        ^^^^^^^^^^^^^^^^^^^\n  File "/home/runner/workspace/.pythonlibs/lib/python3.11/site-packages/sqlalchemy/engine/base.py", line 1416, in execute\n    return meth(\n           ^^^^^\n  File "/home/runner/workspace/.pythonlibs/lib/python3.11/site-packages/sqlalchemy/sql/elements.py", line 523, in _execute_on_connection\n    return connection._execute_clauseelement(\n           ^^^^^^^^^^^^^^^^^^^^^^^^^^^^^^^^^^\n  File "/home/runner/workspace/.pythonlibs/lib/python3.11/site-packages/sqlalchemy/engine/base.py", line 1638, in _execute_clauseelement\n    ret = self._execute_context(\n          ^^^^^^^^^^^^^^^^^^^^^^\n  File "/home/runner/workspace/.pythonlibs/lib/python3.11/site-packages/sqlalchemy/engine/base.py", line 1843, in _execute_context\n    return self._exec_single_context(\n           ^^^^^^^^^^^^^^^^^^^^^^^^^^\n  File "/home/runner/workspace/.pythonlibs/lib/python3.11/site-packages/sqlalchemy/engine/base.py", line 1983, in _exec_single_context\n    self._handle_dbapi_exception(\n  File "/home/runner/workspace/.pythonlibs/lib/python3.11/site-packages/sqlalchemy/engine/base.py", line 2352, in _handle_dbapi_exception\n    raise sqlalchemy_exception.with_traceback(exc_info[2]) from e\n  File "/home/runner/workspace/.pythonlibs/lib/python3.11/site-packages/sqlalchemy/engine/base.py", line 1964, in _exec_single_context\n    self.dialect.do_execute(\n  File "/home/runner/workspace/.pythonlibs/lib/python3.11/site-packages/sqlalchemy/engine/default.py", line 945, in do_execute\n    cursor.execute(statement, parameters)\n', 'suggestions': ['Verify database connection settings', 'Check for invalid queries or constraints', 'Ensure all required fields are provided']}
[2025-04-13 04:45:55] [ERROR] Unhandled Exception: {'error_type': 'Database Error', 'error_message': '(psycopg2.errors.NotNullViolation) null value in column "post_id" of relation "club_post_like" violates not-null constraint\nDETAIL:  Failing row contains (2, null, 149, 2025-04-13 03:58:11.404953).\n\n[SQL: UPDATE club_post_like SET post_id=%(post_id)s WHERE club_post_like.id = %(club_post_like_id)s]\n[parameters: {\'post_id\': None, \'club_post_like_id\': 2}]\n(Background on this error at: https://sqlalche.me/e/20/gkpj)', 'error_details': None, 'file_name': None, 'line_number': None, 'code_snippet': None, 'traceback': '  File "/home/runner/workspace/.pythonlibs/lib/python3.11/site-packages/flask/app.py", line 867, in full_dispatch_request\n    rv = self.dispatch_request()\n         ^^^^^^^^^^^^^^^^^^^^^^^\n  File "/home/runner/workspace/.pythonlibs/lib/python3.11/site-packages/flask/app.py", line 852, in dispatch_request\n    return self.ensure_sync(self.view_functions[rule.endpoint])(**view_args)\n           ^^^^^^^^^^^^^^^^^^^^^^^^^^^^^^^^^^^^^^^^^^^^^^^^^^^^^^^^^^^^^^^^^\n  File "/home/runner/workspace/.pythonlibs/lib/python3.11/site-packages/flask_login/utils.py", line 290, in decorated_view\n    return current_app.ensure_sync(func)(*args, **kwargs)\n           ^^^^^^^^^^^^^^^^^^^^^^^^^^^^^^^^^^^^^^^^^^^^^^\n  File "/home/runner/workspace/app.py", line 3813, in manage_club_post\n    db.session.commit()\n  File "/home/runner/workspace/.pythonlibs/lib/python3.11/site-packages/sqlalchemy/orm/scoping.py", line 599, in commit\n    return self._proxied.commit()\n           ^^^^^^^^^^^^^^^^^^^^^^\n  File "/home/runner/workspace/.pythonlibs/lib/python3.11/site-packages/sqlalchemy/orm/session.py", line 2032, in commit\n    trans.commit(_to_root=True)\n  File "<string>", line 2, in commit\n  File "/home/runner/workspace/.pythonlibs/lib/python3.11/site-packages/sqlalchemy/orm/state_changes.py", line 139, in _go\n    ret_value = fn(self, *arg, **kw)\n                ^^^^^^^^^^^^^^^^^^^^\n  File "/home/runner/workspace/.pythonlibs/lib/python3.11/site-packages/sqlalchemy/orm/session.py", line 1313, in commit\n    self._prepare_impl()\n  File "<string>", line 2, in _prepare_impl\n  File "/home/runner/workspace/.pythonlibs/lib/python3.11/site-packages/sqlalchemy/orm/state_changes.py", line 139, in _go\n    ret_value = fn(self, *arg, **kw)\n                ^^^^^^^^^^^^^^^^^^^^\n  File "/home/runner/workspace/.pythonlibs/lib/python3.11/site-packages/sqlalchemy/orm/session.py", line 1288, in _prepare_impl\n    self.session.flush()\n  File "/home/runner/workspace/.pythonlibs/lib/python3.11/site-packages/sqlalchemy/orm/session.py", line 4353, in flush\n    self._flush(objects)\n  File "/home/runner/workspace/.pythonlibs/lib/python3.11/site-packages/sqlalchemy/orm/session.py", line 4488, in _flush\n    with util.safe_reraise():\n  File "/home/runner/workspace/.pythonlibs/lib/python3.11/site-packages/sqlalchemy/util/langhelpers.py", line 146, in __exit__\n    raise exc_value.with_traceback(exc_tb)\n  File "/home/runner/workspace/.pythonlibs/lib/python3.11/site-packages/sqlalchemy/orm/session.py", line 4449, in _flush\n    flush_context.execute()\n  File "/home/runner/workspace/.pythonlibs/lib/python3.11/site-packages/sqlalchemy/orm/unitofwork.py", line 466, in execute\n    rec.execute(self)\n  File "/home/runner/workspace/.pythonlibs/lib/python3.11/site-packages/sqlalchemy/orm/unitofwork.py", line 642, in execute\n    util.preloaded.orm_persistence.save_obj(\n  File "/home/runner/workspace/.pythonlibs/lib/python3.11/site-packages/sqlalchemy/orm/persistence.py", line 85, in save_obj\n    _emit_update_statements(\n  File "/home/runner/workspace/.pythonlibs/lib/python3.11/site-packages/sqlalchemy/orm/persistence.py", line 912, in _emit_update_statements\n    c = connection.execute(\n        ^^^^^^^^^^^^^^^^^^^\n  File "/home/runner/workspace/.pythonlibs/lib/python3.11/site-packages/sqlalchemy/engine/base.py", line 1416, in execute\n    return meth(\n           ^^^^^\n  File "/home/runner/workspace/.pythonlibs/lib/python3.11/site-packages/sqlalchemy/sql/elements.py", line 523, in _execute_on_connection\n    return connection._execute_clauseelement(\n           ^^^^^^^^^^^^^^^^^^^^^^^^^^^^^^^^^^\n  File "/home/runner/workspace/.pythonlibs/lib/python3.11/site-packages/sqlalchemy/engine/base.py", line 1638, in _execute_clauseelement\n    ret = self._execute_context(\n          ^^^^^^^^^^^^^^^^^^^^^^\n  File "/home/runner/workspace/.pythonlibs/lib/python3.11/site-packages/sqlalchemy/engine/base.py", line 1843, in _execute_context\n    return self._exec_single_context(\n           ^^^^^^^^^^^^^^^^^^^^^^^^^^\n  File "/home/runner/workspace/.pythonlibs/lib/python3.11/site-packages/sqlalchemy/engine/base.py", line 1983, in _exec_single_context\n    self._handle_dbapi_exception(\n  File "/home/runner/workspace/.pythonlibs/lib/python3.11/site-packages/sqlalchemy/engine/base.py", line 2352, in _handle_dbapi_exception\n    raise sqlalchemy_exception.with_traceback(exc_info[2]) from e\n  File "/home/runner/workspace/.pythonlibs/lib/python3.11/site-packages/sqlalchemy/engine/base.py", line 1964, in _exec_single_context\n    self.dialect.do_execute(\n  File "/home/runner/workspace/.pythonlibs/lib/python3.11/site-packages/sqlalchemy/engine/default.py", line 945, in do_execute\n    cursor.execute(statement, parameters)\n', 'suggestions': ['Verify database connection settings', 'Check for invalid queries or constraints', 'Ensure all required fields are provided']}
[2025-04-13 04:45:55] [INFO] 172.31.128.25 - - [13/Apr/2025 04:45:55] "DELETE /api/clubs/28/posts/5 HTTP/1.1" 500 -
Traceback (most recent call last):
  File "/home/runner/workspace/.pythonlibs/lib/python3.11/site-packages/sqlalchemy/engine/base.py", line 1964, in _exec_single_context
    self.dialect.do_execute(
  File "/home/runner/workspace/.pythonlibs/lib/python3.11/site-packages/sqlalchemy/engine/default.py", line 945, in do_execute
    cursor.execute(statement, parameters)
psycopg2.errors.NotNullViolation: null value in column "post_id" of relation "club_post_like" violates not-null constraint
DETAIL:  Failing row contains (2, null, 149, 2025-04-13 03:58:11.404953).


The above exception was the direct cause of the following exception:

Traceback (most recent call last):
  File "/home/runner/workspace/.pythonlibs/lib/python3.11/site-packages/flask/app.py", line 867, in full_dispatch_request
    rv = self.dispatch_request()
         ^^^^^^^^^^^^^^^^^^^^^^^
  File "/home/runner/workspace/.pythonlibs/lib/python3.11/site-packages/flask/app.py", line 852, in dispatch_request
    return self.ensure_sync(self.view_functions[rule.endpoint])(**view_args)
           ^^^^^^^^^^^^^^^^^^^^^^^^^^^^^^^^^^^^^^^^^^^^^^^^^^^^^^^^^^^^^^^^^
  File "/home/runner/workspace/.pythonlibs/lib/python3.11/site-packages/flask_login/utils.py", line 290, in decorated_view
    return current_app.ensure_sync(func)(*args, **kwargs)
           ^^^^^^^^^^^^^^^^^^^^^^^^^^^^^^^^^^^^^^^^^^^^^^
  File "/home/runner/workspace/app.py", line 3813, in manage_club_post
    db.session.commit()
  File "/home/runner/workspace/.pythonlibs/lib/python3.11/site-packages/sqlalchemy/orm/scoping.py", line 599, in commit
    return self._proxied.commit()
           ^^^^^^^^^^^^^^^^^^^^^^
  File "/home/runner/workspace/.pythonlibs/lib/python3.11/site-packages/sqlalchemy/orm/session.py", line 2032, in commit
    trans.commit(_to_root=True)
  File "<string>", line 2, in commit
  File "/home/runner/workspace/.pythonlibs/lib/python3.11/site-packages/sqlalchemy/orm/state_changes.py", line 139, in _go
    ret_value = fn(self, *arg, **kw)
                ^^^^^^^^^^^^^^^^^^^^
  File "/home/runner/workspace/.pythonlibs/lib/python3.11/site-packages/sqlalchemy/orm/session.py", line 1313, in commit
    self._prepare_impl()
  File "<string>", line 2, in _prepare_impl
  File "/home/runner/workspace/.pythonlibs/lib/python3.11/site-packages/sqlalchemy/orm/state_changes.py", line 139, in _go
    ret_value = fn(self, *arg, **kw)
                ^^^^^^^^^^^^^^^^^^^^
  File "/home/runner/workspace/.pythonlibs/lib/python3.11/site-packages/sqlalchemy/orm/session.py", line 1288, in _prepare_impl
    self.session.flush()
  File "/home/runner/workspace/.pythonlibs/lib/python3.11/site-packages/sqlalchemy/orm/session.py", line 4353, in flush
    self._flush(objects)
  File "/home/runner/workspace/.pythonlibs/lib/python3.11/site-packages/sqlalchemy/orm/session.py", line 4488, in _flush
    with util.safe_reraise():
  File "/home/runner/workspace/.pythonlibs/lib/python3.11/site-packages/sqlalchemy/util/langhelpers.py", line 146, in __exit__
    raise exc_value.with_traceback(exc_tb)
  File "/home/runner/workspace/.pythonlibs/lib/python3.11/site-packages/sqlalchemy/orm/session.py", line 4449, in _flush
    flush_context.execute()
  File "/home/runner/workspace/.pythonlibs/lib/python3.11/site-packages/sqlalchemy/orm/unitofwork.py", line 466, in execute
    rec.execute(self)
  File "/home/runner/workspace/.pythonlibs/lib/python3.11/site-packages/sqlalchemy/orm/unitofwork.py", line 642, in execute
    util.preloaded.orm_persistence.save_obj(
  File "/home/runner/workspace/.pythonlibs/lib/python3.11/site-packages/sqlalchemy/orm/persistence.py", line 85, in save_obj
    _emit_update_statements(
  File "/home/runner/workspace/.pythonlibs/lib/python3.11/site-packages/sqlalchemy/orm/persistence.py", line 912, in _emit_update_statements
    c = connection.execute(
        ^^^^^^^^^^^^^^^^^^^
  File "/home/runner/workspace/.pythonlibs/lib/python3.11/site-packages/sqlalchemy/engine/base.py", line 1416, in execute
    return meth(
           ^^^^^
  File "/home/runner/workspace/.pythonlibs/lib/python3.11/site-packages/sqlalchemy/sql/elements.py", line 523, in _execute_on_connection
    return connection._execute_clauseelement(
           ^^^^^^^^^^^^^^^^^^^^^^^^^^^^^^^^^^
  File "/home/runner/workspace/.pythonlibs/lib/python3.11/site-packages/sqlalchemy/engine/base.py", line 1638, in _execute_clauseelement
    ret = self._execute_context(
          ^^^^^^^^^^^^^^^^^^^^^^
  File "/home/runner/workspace/.pythonlibs/lib/python3.11/site-packages/sqlalchemy/engine/base.py", line 1843, in _execute_context
    return self._exec_single_context(
           ^^^^^^^^^^^^^^^^^^^^^^^^^^
  File "/home/runner/workspace/.pythonlibs/lib/python3.11/site-packages/sqlalchemy/engine/base.py", line 1983, in _exec_single_context
    self._handle_dbapi_exception(
  File "/home/runner/workspace/.pythonlibs/lib/python3.11/site-packages/sqlalchemy/engine/base.py", line 2352, in _handle_dbapi_exception
    raise sqlalchemy_exception.with_traceback(exc_info[2]) from e
  File "/home/runner/workspace/.pythonlibs/lib/python3.11/site-packages/sqlalchemy/engine/base.py", line 1964, in _exec_single_context
    self.dialect.do_execute(
  File "/home/runner/workspace/.pythonlibs/lib/python3.11/site-packages/sqlalchemy/engine/default.py", line 945, in do_execute
    cursor.execute(statement, parameters)
sqlalchemy.exc.IntegrityError: (psycopg2.errors.NotNullViolation) null value in column "post_id" of relation "club_post_like" violates not-null constraint
DETAIL:  Failing row contains (2, null, 149, 2025-04-13 03:58:11.404953).

[SQL: UPDATE club_post_like SET post_id=%(post_id)s WHERE club_post_like.id = %(club_post_like_id)s]
[parameters: {'post_id': None, 'club_post_like_id': 2}]
(Background on this error at: https://sqlalche.me/e/20/gkpj)

During handling of the above exception, another exception occurred:

Traceback (most recent call last):
  File "/home/runner/workspace/.pythonlibs/lib/python3.11/site-packages/flask/app.py", line 1478, in __call__
    return self.wsgi_app(environ, start_response)
           ^^^^^^^^^^^^^^^^^^^^^^^^^^^^^^^^^^^^^^
  File "/home/runner/workspace/.pythonlibs/lib/python3.11/site-packages/flask/app.py", line 1458, in wsgi_app
    response = self.handle_exception(e)
               ^^^^^^^^^^^^^^^^^^^^^^^^
  File "/home/runner/workspace/.pythonlibs/lib/python3.11/site-packages/flask/app.py", line 1455, in wsgi_app
    response = self.full_dispatch_request()
               ^^^^^^^^^^^^^^^^^^^^^^^^^^^^
  File "/home/runner/workspace/.pythonlibs/lib/python3.11/site-packages/flask/app.py", line 869, in full_dispatch_request
    rv = self.handle_user_exception(e)
         ^^^^^^^^^^^^^^^^^^^^^^^^^^^^^
  File "/home/runner/workspace/.pythonlibs/lib/python3.11/site-packages/flask/app.py", line 759, in handle_user_exception
    return self.ensure_sync(handler)(e)
           ^^^^^^^^^^^^^^^^^^^^^^^^^^^^
  File "/home/runner/workspace/app.py", line 193, in handle_error
    return render_template('errors/generic.html', **context), code
           ^^^^^^^^^^^^^^^^^^^^^^^^^^^^^^^^^^^^^^^^^^^^^^^^^^^^^^^
  File "/home/runner/workspace/.pythonlibs/lib/python3.11/site-packages/flask/templating.py", line 152, in render_template
    return _render(app, template, context)
           ^^^^^^^^^^^^^^^^^^^^^^^^^^^^^^^
  File "/home/runner/workspace/.pythonlibs/lib/python3.11/site-packages/flask/templating.py", line 133, in _render
    rv = template.render(context)
         ^^^^^^^^^^^^^^^^^^^^^^^^
  File "/home/runner/workspace/.pythonlibs/lib/python3.11/site-packages/jinja2/environment.py", line 1295, in render
    self.environment.handle_exception()
  File "/home/runner/workspace/.pythonlibs/lib/python3.11/site-packages/jinja2/environment.py", line 942, in handle_exception
    raise rewrite_traceback_stack(source=source)
  File "/home/runner/workspace/templates/errors/generic.html", line 1, in top-level template code
    {% extends "errors/base_error.html" %}
  File "/home/runner/workspace/templates/errors/base_error.html", line 1, in top-level template code
    {% extends "base.html" %}
  File "/home/runner/workspace/templates/base.html", line 33, in top-level template code
    {% if current_user.is_authenticated %}
  File "/home/runner/workspace/.pythonlibs/lib/python3.11/site-packages/jinja2/environment.py", line 490, in getattr
    return getattr(obj, attribute)
           ^^^^^^^^^^^^^^^^^^^^^^^
  File "/home/runner/workspace/.pythonlibs/lib/python3.11/site-packages/flask_login/mixins.py", line 17, in is_authenticated
    return self.is_active
           ^^^^^^^^^^^^^^
  File "/home/runner/workspace/.pythonlibs/lib/python3.11/site-packages/sqlalchemy/orm/attributes.py", line 566, in __get__
    return self.impl.get(state, dict_)  # type: ignore[no-any-return]
           ^^^^^^^^^^^^^^^^^^^^^^^^^^^^^^^^^^^^^^^^^^^^^^^^^^^^^^^^^^
  File "/home/runner/workspace/.pythonlibs/lib/python3.11/site-packages/sqlalchemy/orm/attributes.py", line 1086, in get
    value = self._fire_loader_callables(state, key, passive)
            ^^^^^^^^^^^^^^^^^^^^^^^^^^^^^^^^^^^^^^^^^^^^^^^^
  File "/home/runner/workspace/.pythonlibs/lib/python3.11/site-packages/sqlalchemy/orm/attributes.py", line 1116, in _fire_loader_callables
    return state._load_expired(state, passive)
           ^^^^^^^^^^^^^^^^^^^^^^^^^^^^^^^^^^^
  File "/home/runner/workspace/.pythonlibs/lib/python3.11/site-packages/sqlalchemy/orm/state.py", line 803, in _load_expired
    self.manager.expired_attribute_loader(self, toload, passive)
  File "/home/runner/workspace/.pythonlibs/lib/python3.11/site-packages/sqlalchemy/orm/loading.py", line 1670, in load_scalar_attributes
    result = load_on_ident(
             ^^^^^^^^^^^^^^
  File "/home/runner/workspace/.pythonlibs/lib/python3.11/site-packages/sqlalchemy/orm/loading.py", line 509, in load_on_ident
    return load_on_pk_identity(
           ^^^^^^^^^^^^^^^^^^^^
  File "/home/runner/workspace/.pythonlibs/lib/python3.11/site-packages/sqlalchemy/orm/loading.py", line 694, in load_on_pk_identity
    session.execute(
  File "/home/runner/workspace/.pythonlibs/lib/python3.11/site-packages/sqlalchemy/orm/session.py", line 2365, in execute
    return self._execute_internal(
           ^^^^^^^^^^^^^^^^^^^^^^^
  File "/home/runner/workspace/.pythonlibs/lib/python3.11/site-packages/sqlalchemy/orm/session.py", line 2241, in _execute_internal
    conn = self._connection_for_bind(bind)
           ^^^^^^^^^^^^^^^^^^^^^^^^^^^^^^^
  File "/home/runner/workspace/.pythonlibs/lib/python3.11/site-packages/sqlalchemy/orm/session.py", line 2110, in _connection_for_bind
    return trans._connection_for_bind(engine, execution_options)
           ^^^^^^^^^^^^^^^^^^^^^^^^^^^^^^^^^^^^^^^^^^^^^^^^^^^^^
  File "<string>", line 2, in _connection_for_bind
  File "/home/runner/workspace/.pythonlibs/lib/python3.11/site-packages/sqlalchemy/orm/state_changes.py", line 103, in _go
    self._raise_for_prerequisite_state(fn.__name__, current_state)
  File "/home/runner/workspace/.pythonlibs/lib/python3.11/site-packages/sqlalchemy/orm/session.py", line 973, in _raise_for_prerequisite_state
    raise sa_exc.PendingRollbackError(
sqlalchemy.exc.PendingRollbackError: This Session's transaction has been rolled back due to a previous exception during flush. To begin a new transaction with this Session, first issue Session.rollback(). Original exception was: (psycopg2.errors.NotNullViolation) null value in column "post_id" of relation "club_post_like" violates not-null constraint
DETAIL:  Failing row contains (2, null, 149, 2025-04-13 03:58:11.404953).

[SQL: UPDATE club_post_like SET post_id=%(post_id)s WHERE club_post_like.id = %(club_post_like_id)s]
[parameters: {'post_id': None, 'club_post_like_id': 2}]
(Background on this error at: https://sqlalche.me/e/20/gkpj) (Background on this error at: https://sqlalche.me/e/20/7s2a)
