tent, site.python_content AS site_python_content, site.pixi_content AS site_pixi_content, site.is_public AS site_is_public, site.created_at AS site_created_at, site.updated_at AS site_updated_at, site.user_id AS site_user_id, site.view_count AS site_view_count, site.analytics_enabled AS site_analytics_enabled \nFROM site \nWHERE site.user_id = %(user_id_1)s ORDER BY site.updated_at DESC]\n[parameters: {'user_id_1': 149}]\n(Background on this error at: https://sqlalche.me/e/20/f405)", 'error_details': None, 'file_name': None, 'line_number': None, 'code_snippet': None, 'traceback': '  File "/home/runner/workspace/.pythonlibs/lib/python3.11/site-packages/flask/app.py", line 867, in full_dispatch_request\n    rv = self.dispatch_request()\n         ^^^^^^^^^^^^^^^^^^^^^^^\n  File "/home/runner/workspace/.pythonlibs/lib/python3.11/site-packages/flask/app.py", line 852, in dispatch_request\n    return self.ensure_sync(self.view_functions[rule.endpoint])(**view_args)\n           ^^^^^^^^^^^^^^^^^^^^^^^^^^^^^^^^^^^^^^^^^^^^^^^^^^^^^^^^^^^^^^^^^\n  File "/home/runner/workspace/.pythonlibs/lib/python3.11/site-packages/flask_login/utils.py", line 290, in decorated_view\n    return current_app.ensure_sync(func)(*args, **kwargs)\n           ^^^^^^^^^^^^^^^^^^^^^^^^^^^^^^^^^^^^^^^^^^^^^^\n  File "/home/runner/workspace/app.py", line 598, in welcome\n    Site.updated_at.desc()).all()\n                            ^^^^^\n  File "/home/runner/workspace/.pythonlibs/lib/python3.11/site-packages/sqlalchemy/orm/query.py", line 2704, in all\n    return self._iter().all()  # type: ignore\n           ^^^^^^^^^^^^\n  File "/home/runner/workspace/.pythonlibs/lib/python3.11/site-packages/sqlalchemy/orm/query.py", line 2858, in _iter\n    result: Union[ScalarResult[_T], Result[_T]] = self.session.execute(\n                                                  ^^^^^^^^^^^^^^^^^^^^^\n  File "/home/runner/workspace/.pythonlibs/lib/python3.11/site-packages/sqlalchemy/orm/session.py", line 2365, in execute\n    return self._execute_internal(\n           ^^^^^^^^^^^^^^^^^^^^^^^\n  File "/home/runner/workspace/.pythonlibs/lib/python3.11/site-packages/sqlalchemy/orm/session.py", line 2251, in _execute_internal\n    result: Result[Any] = compile_state_cls.orm_execute_statement(\n                          ^^^^^^^^^^^^^^^^^^^^^^^^^^^^^^^^^^^^^^^^\n  File "/home/runner/workspace/.pythonlibs/lib/python3.11/site-packages/sqlalchemy/orm/context.py", line 306, in orm_execute_statement\n    result = conn.execute(\n             ^^^^^^^^^^^^^\n  File "/home/runner/workspace/.pythonlibs/lib/python3.11/site-packages/sqlalchemy/engine/base.py", line 1416, in execute\n    return meth(\n           ^^^^^\n  File "/home/runner/workspace/.pythonlibs/lib/python3.11/site-packages/sqlalchemy/sql/elements.py", line 523, in _execute_on_connection\n    return connection._execute_clauseelement(\n           ^^^^^^^^^^^^^^^^^^^^^^^^^^^^^^^^^^\n  File "/home/runner/workspace/.pythonlibs/lib/python3.11/site-packages/sqlalchemy/engine/base.py", line 1638, in _execute_clauseelement\n    ret = self._execute_context(\n          ^^^^^^^^^^^^^^^^^^^^^^\n  File "/home/runner/workspace/.pythonlibs/lib/python3.11/site-packages/sqlalchemy/engine/base.py", line 1843, in _execute_context\n    return self._exec_single_context(\n           ^^^^^^^^^^^^^^^^^^^^^^^^^^\n  File "/home/runner/workspace/.pythonlibs/lib/python3.11/site-packages/sqlalchemy/engine/base.py", line 1983, in _exec_single_context\n    self._handle_dbapi_exception(\n  File "/home/runner/workspace/.pythonlibs/lib/python3.11/site-packages/sqlalchemy/engine/base.py", line 2352, in _handle_dbapi_exception\n    raise sqlalchemy_exception.with_traceback(exc_info[2]) from e\n  File "/home/runner/workspace/.pythonlibs/lib/python3.11/site-packages/sqlalchemy/engine/base.py", line 1964, in _exec_single_context\n    self.dialect.do_execute(\n  File "/home/runner/workspace/.pythonlibs/lib/python3.11/site-packages/sqlalchemy/engine/default.py", line 945, in do_execute\n    cursor.execute(statement, parameters)\n', 'suggestions': ['Verify database connection settings', 'Check for invalid queries or constraints', 'Ensure all required fields are provided']}
[2025-04-15 18:07:24] [INFO] 172.31.128.46 - - [15/Apr/2025 18:07:24] "GET /welcome HTTP/1.1" 0 -
[2025-04-15 18:07:24,939] [ERROR] Unhandled Exception: {'error_type': 'Database Error', 'error_message': "(psycopg2.errors.UndefinedColumn) column site.pixi_content does not exist\nLINE 1: ...tent, site.python_content AS site_python_content, site.pixi_...\n                                                             ^\n\n[SQL: SELECT site.id AS site_id, site.name AS site_name, site.slug AS site_slug, site.site_type AS site_site_type, site.html_content AS site_html_content, site.python_content AS site_python_content, site.pixi_content AS site_pixi_content, site.is_public AS site_is_public, site.created_at AS site_created_at, site.updated_at AS site_updated_at, site.user_id AS site_user_id, site.view_count AS site_view_count, site.analytics_enabled AS site_analytics_enabled \nFROM site \nWHERE site.user_id = %(user_id_1)s ORDER BY site.updated_at DESC]\n[parameters: {'user_id_1': 149}]\n(Background on this error at: https://sqlalche.me/e/20/f405)", 'error_details': None, 'file_name': None, 'line_number': None, 'code_snippet': None, 'traceback': '  File "/home/runner/workspace/.pythonlibs/lib/python3.11/site-packages/flask/app.py", line 867, in full_dispatch_request\n    rv = self.dispatch_request()\n         ^^^^^^^^^^^^^^^^^^^^^^^\n  File "/home/runner/workspace/.pythonlibs/lib/python3.11/site-packages/flask/app.py", line 852, in dispatch_request\n    return self.ensure_sync(self.view_functions[rule.endpoint])(**view_args)\n           ^^^^^^^^^^^^^^^^^^^^^^^^^^^^^^^^^^^^^^^^^^^^^^^^^^^^^^^^^^^^^^^^^\n  File "/home/runner/workspace/.pythonlibs/lib/python3.11/site-packages/flask_login/utils.py", line 290, in decorated_view\n    return current_app.ensure_sync(func)(*args, **kwargs)\n           ^^^^^^^^^^^^^^^^^^^^^^^^^^^^^^^^^^^^^^^^^^^^^^\n  File "/home/runner/workspace/app.py", line 598, in welcome\n    Site.updated_at.desc()).all()\n                            ^^^^^\n  File "/home/runner/workspace/.pythonlibs/lib/python3.11/site-packages/sqlalchemy/orm/query.py", line 2704, in all\n    return self._iter().all()  # type: ignore\n           ^^^^^^^^^^^^\n  File "/home/runner/workspace/.pythonlibs/lib/python3.11/site-packages/sqlalchemy/orm/query.py", line 2858, in _iter\n    result: Union[ScalarResult[_T], Result[_T]] = self.session.execute(\n                                                  ^^^^^^^^^^^^^^^^^^^^^\n  File "/home/runner/workspace/.pythonlibs/lib/python3.11/site-packages/sqlalchemy/orm/session.py", line 2365, in execute\n    return self._execute_internal(\n           ^^^^^^^^^^^^^^^^^^^^^^^\n  File "/home/runner/workspace/.pythonlibs/lib/python3.11/site-packages/sqlalchemy/orm/session.py", line 2251, in _execute_internal\n    result: Result[Any] = compile_state_cls.orm_execute_statement(\n                          ^^^^^^^^^^^^^^^^^^^^^^^^^^^^^^^^^^^^^^^^\n  File "/home/runner/workspace/.pythonlibs/lib/python3.11/site-packages/sqlalchemy/orm/context.py", line 306, in orm_execute_statement\n    result = conn.execute(\n             ^^^^^^^^^^^^^\n  File "/home/runner/workspace/.pythonlibs/lib/python3.11/site-packages/sqlalchemy/engine/base.py", line 1416, in execute\n    return meth(\n           ^^^^^\n  File "/home/runner/workspace/.pythonlibs/lib/python3.11/site-packages/sqlalchemy/sql/elements.py", line 523, in _execute_on_connection\n    return connection._execute_clauseelement(\n           ^^^^^^^^^^^^^^^^^^^^^^^^^^^^^^^^^^\n  File "/home/runner/workspace/.pythonlibs/lib/python3.11/site-packages/sqlalchemy/engine/base.py", line 1638, in _execute_clauseelement\n    ret = self._execute_context(\n          ^^^^^^^^^^^^^^^^^^^^^^\n  File "/home/runner/workspace/.pythonlibs/lib/python3.11/site-packages/sqlalchemy/engine/base.py", line 1843, in _execute_context\n    return self._exec_single_context(\n           ^^^^^^^^^^^^^^^^^^^^^^^^^^\n  File "/home/runner/workspace/.pythonlibs/lib/python3.11/site-packages/sqlalchemy/engine/base.py", line 1983, in _exec_single_context\n    self._handle_dbapi_exception(\n  File "/home/runner/workspace/.pythonlibs/lib/python3.11/site-packages/sqlalchemy/engine/base.py", line 2352, in _handle_dbapi_exception\n    raise sqlalchemy_exception.with_traceback(exc_info[2]) from e\n  File "/home/runner/workspace/.pythonlibs/lib/python3.11/site-packages/sqlalchemy/engine/base.py", line 1964, in _exec_single_context\n    self.dialect.do_execute(\n  File "/home/runner/workspace/.pythonlibs/lib/python3.11/site-packages/sqlalchemy/engine/default.py", line 945, in do_execute\n    cursor.execute(statement, parameters)\n', 'suggestions': ['Verify database connection settings', 'Check for invalid queries or constraints', 'Ensure all required fields are provided']}
[2025-04-15 18:07:24] [ERROR] Unhandled Exception: {'error_type': 'Database Error', 'error_message': "(psycopg2.errors.UndefinedColumn) column site.pixi_content does not exist\nLINE 1: ...tent, site.python_content AS site_python_content, site.pixi_...\n                                                             ^\n\n[SQL: SELECT site.id AS site_id, site.name AS site_name, site.slug AS site_slug, site.site_type AS site_site_type, site.html_content AS site_html_content, site.python_content AS site_python_content, site.pixi_content AS site_pixi_content, site.is_public AS site_is_public, site.created_at AS site_created_at, site.updated_at AS site_updated_at, site.user_id AS site_user_id, site.view_count AS site_view_count, site.analytics_enabled AS site_analytics_enabled \nFROM site \nWHERE site.user_id = %(user_id_1)s ORDER BY site.updated_at DESC]\n[parameters: {'user_id_1': 149}]\n(Background on this error at: https://sqlalche.me/e/20/f405)", 'error_details': None, 'file_name': None, 'line_number': None, 'code_snippet': None, 'traceback': '  File "/home/runner/workspace/.pythonlibs/lib/python3.11/site-packages/flask/app.py", line 867, in full_dispatch_request\n    rv = self.dispatch_request()\n         ^^^^^^^^^^^^^^^^^^^^^^^\n  File "/home/runner/workspace/.pythonlibs/lib/python3.11/site-packages/flask/app.py", line 852, in dispatch_request\n    return self.ensure_sync(self.view_functions[rule.endpoint])(**view_args)\n           ^^^^^^^^^^^^^^^^^^^^^^^^^^^^^^^^^^^^^^^^^^^^^^^^^^^^^^^^^^^^^^^^^\n  File "/home/runner/workspace/.pythonlibs/lib/python3.11/site-packages/flask_login/utils.py", line 290, in decorated_view\n    return current_app.ensure_sync(func)(*args, **kwargs)\n           ^^^^^^^^^^^^^^^^^^^^^^^^^^^^^^^^^^^^^^^^^^^^^^\n  File "/home/runner/workspace/app.py", line 598, in welcome\n    Site.updated_at.desc()).all()\n                            ^^^^^\n  File "/home/runner/workspace/.pythonlibs/lib/python3.11/site-packages/sqlalchemy/orm/query.py", line 2704, in all\n    return self._iter().all()  # type: ignore\n           ^^^^^^^^^^^^\n  File "/home/runner/workspace/.pythonlibs/lib/python3.11/site-packages/sqlalchemy/orm/query.py", line 2858, in _iter\n    result: Union[ScalarResult[_T], Result[_T]] = self.session.execute(\n                                                  ^^^^^^^^^^^^^^^^^^^^^\n  File "/home/runner/workspace/.pythonlibs/lib/python3.11/site-packages/sqlalchemy/orm/session.py", line 2365, in execute\n    return self._execute_internal(\n           ^^^^^^^^^^^^^^^^^^^^^^^\n  File "/home/runner/workspace/.pythonlibs/lib/python3.11/site-packages/sqlalchemy/orm/session.py", line 2251, in _execute_internal\n    result: Result[Any] = compile_state_cls.orm_execute_statement(\n                          ^^^^^^^^^^^^^^^^^^^^^^^^^^^^^^^^^^^^^^^^\n  File "/home/runner/workspace/.pythonlibs/lib/python3.11/site-packages/sqlalchemy/orm/context.py", line 306, in orm_execute_statement\n    result = conn.execute(\n             ^^^^^^^^^^^^^\n  File "/home/runner/workspace/.pythonlibs/lib/python3.11/site-packages/sqlalchemy/engine/base.py", line 1416, in execute\n    return meth(\n           ^^^^^\n  File "/home/runner/workspace/.pythonlibs/lib/python3.11/site-packages/sqlalchemy/sql/elements.py", line 523, in _execute_on_connection\n    return connection._execute_clauseelement(\n           ^^^^^^^^^^^^^^^^^^^^^^^^^^^^^^^^^^\n  File "/home/runner/workspace/.pythonlibs/lib/python3.11/site-packages/sqlalchemy/engine/base.py", line 1638, in _execute_clauseelement\n    ret = self._execute_context(\n          ^^^^^^^^^^^^^^^^^^^^^^\n  File "/home/runner/workspace/.pythonlibs/lib/python3.11/site-packages/sqlalchemy/engine/base.py", line 1843, in _execute_context\n    return self._exec_single_context(\n           ^^^^^^^^^^^^^^^^^^^^^^^^^^\n  File "/home/runner/workspace/.pythonlibs/lib/python3.11/site-packages/sqlalchemy/engine/base.py", line 1983, in _exec_single_context\n    self._handle_dbapi_exception(\n  File "/home/runner/workspace/.pythonlibs/lib/python3.11/site-packages/sqlalchemy/engine/base.py", line 2352, in _handle_dbapi_exception\n    raise sqlalchemy_exception.with_traceback(exc_info[2]) from e\n  File "/home/runner/workspace/.pythonlibs/lib/python3.11/site-packages/sqlalchemy/engine/base.py", line 1964, in _exec_single_context\n    self.dialect.do_execute(\n  File "/home/runner/workspace/.pythonlibs/lib/python3.11/site-packages/sqlalchemy/engine/default.py", line 945, in do_execute\n    cursor.execute(statement, parameters)\n', 'suggestions': ['Verify database connection settings', 'Check for invalid queries or constraints', 'Ensure all required fields are provided']}
[2025-04-15 18:07:24] [INFO] 172.31.128.46 - - [15/Apr/2025 18:07:24] "GET /welcome HTTP/1.1" 0 -
[2025-04-15 18:07:25,199] [ERROR] Unhandled Exception: {'error_type': 'Database Error', 'error_message': "(psycopg2.errors.UndefinedColumn) column site.pixi_content does not exist\nLINE 1: ...tent, site.python_content AS site_python_content, site.pixi_...\n                                                             ^\n\n[SQL: SELECT site.id AS site_id, site.name AS site_name, site.slug AS site_slug, site.site_type AS site_site_type, site.html_content AS site_html_content, site.python_content AS site_python_content, site.pixi_content AS site_pixi_content, site.is_public AS site_is_public, site.created_at AS site_created_at, site.updated_at AS site_updated_at, site.user_id AS site_user_id, site.view_count AS site_view_count, site.analytics_enabled AS site_analytics_enabled \nFROM site \nWHERE site.user_id = %(user_id_1)s ORDER BY site.updated_at DESC]\n[parameters: {'user_id_1': 149}]\n(Background on this error at: https://sqlalche.me/e/20/f405)", 'error_details': None, 'file_name': None, 'line_number': None, 'code_snippet': None, 'traceback': '  File "/home/runner/workspace/.pythonlibs/lib/python3.11/site-packages/flask/app.py", line 867, in full_dispatch_request\n    rv = self.dispatch_request()\n         ^^^^^^^^^^^^^^^^^^^^^^^\n  File "/home/runner/workspace/.pythonlibs/lib/python3.11/site-packages/flask/app.py", line 852, in dispatch_request\n    return self.ensure_sync(self.view_functions[rule.endpoint])(**view_args)\n           ^^^^^^^^^^^^^^^^^^^^^^^^^^^^^^^^^^^^^^^^^^^^^^^^^^^^^^^^^^^^^^^^^\n  File "/home/runner/workspace/.pythonlibs/lib/python3.11/site-packages/flask_login/utils.py", line 290, in decorated_view\n    return current_app.ensure_sync(func)(*args, **kwargs)\n           ^^^^^^^^^^^^^^^^^^^^^^^^^^^^^^^^^^^^^^^^^^^^^^\n  File "/home/runner/workspace/app.py", line 598, in welcome\n    Site.updated_at.desc()).all()\n                            ^^^^^\n  File "/home/runner/workspace/.pythonlibs/lib/python3.11/site-packages/sqlalchemy/orm/query.py", line 2704, in all\n    return self._iter().all()  # type: ignore\n           ^^^^^^^^^^^^\n  File "/home/runner/workspace/.pythonlibs/lib/python3.11/site-packages/sqlalchemy/orm/query.py", line 2858, in _iter\n    result: Union[ScalarResult[_T], Result[_T]] = self.session.execute(\n                                                  ^^^^^^^^^^^^^^^^^^^^^\n  File "/home/runner/workspace/.pythonlibs/lib/python3.11/site-packages/sqlalchemy/orm/session.py", line 2365, in execute\n    return self._execute_internal(\n           ^^^^^^^^^^^^^^^^^^^^^^^\n  File "/home/runner/workspace/.pythonlibs/lib/python3.11/site-packages/sqlalchemy/orm/session.py", line 2251, in _execute_internal\n    result: Result[Any] = compile_state_cls.orm_execute_statement(\n                          ^^^^^^^^^^^^^^^^^^^^^^^^^^^^^^^^^^^^^^^^\n  File "/home/runner/workspace/.pythonlibs/lib/python3.11/site-packages/sqlalchemy/orm/context.py", line 306, in orm_execute_statement\n    result = conn.execute(\n             ^^^^^^^^^^^^^\n  File "/home/runner/workspace/.pythonlibs/lib/python3.11/site-packages/sqlalchemy/engine/base.py", line 1416, in execute\n    return meth(\n           ^^^^^\n  File "/home/runner/workspace/.pythonlibs/lib/python3.11/site-packages/sqlalchemy/sql/elements.py", line 523, in _execute_on_connection\n    return connection._execute_clauseelement(\n           ^^^^^^^^^^^^^^^^^^^^^^^^^^^^^^^^^^\n  File "/home/runner/workspace/.pythonlibs/lib/python3.11/site-packages/sqlalchemy/engine/base.py", line 1638, in _execute_clauseelement\n    ret = self._execute_context(\n          ^^^^^^^^^^^^^^^^^^^^^^\n  File "/home/runner/workspace/.pythonlibs/lib/python3.11/site-packages/sqlalchemy/engine/base.py", line 1843, in _execute_context\n    return self._exec_single_context(\n           ^^^^^^^^^^^^^^^^^^^^^^^^^^\n  File "/home/runner/workspace/.pythonlibs/lib/python3.11/site-packages/sqlalchemy/engine/base.py", line 1983, in _exec_single_context\n    self._handle_dbapi_exception(\n  File "/home/runner/workspace/.pythonlibs/lib/python3.11/site-packages/sqlalchemy/engine/base.py", line 2352, in _handle_dbapi_exception\n    raise sqlalchemy_exception.with_traceback(exc_info[2]) from e\n  File "/home/runner/workspace/.pythonlibs/lib/python3.11/site-packages/sqlalchemy/engine/base.py", line 1964, in _exec_single_context\n    self.dialect.do_execute(\n  File "/home/runner/workspace/.pythonlibs/lib/python3.11/site-packages/sqlalchemy/engine/default.py", line 945, in do_execute\n    cursor.execute(statement, parameters)\n', 'suggestions': ['Verify database connection settings', 'Check for invalid queries or constraints', 'Ensure all required fields are provided']}
[2025-04-15 18:07:25] [ERROR] Unhandled Exception: {'error_type': 'Database Error', 'error_message': "(psycopg2.errors.UndefinedColumn) column site.pixi_content does not exist\nLINE 1: ...tent, site.python_content AS site_python_content, site.pixi_...\n                                                             ^\n\n[SQL: SELECT site.id AS site_id, site.name AS site_name, site.slug AS site_slug, site.site_type AS site_site_type, site.html_content AS site_html_content, site.python_content AS site_python_content, site.pixi_content AS site_pixi_content, site.is_public AS site_is_public, site.created_at AS site_created_at, site.updated_at AS site_updated_at, site.user_id AS site_user_id, site.view_count AS site_view_count, site.analytics_enabled AS site_analytics_enabled \nFROM site \nWHERE site.user_id = %(user_id_1)s ORDER BY site.updated_at DESC]\n[parameters: {'user_id_1': 149}]\n(Background on this error at: https://sqlalche.me/e/20/f405)", 'error_details': None, 'file_name': None, 'line_number': None, 'code_snippet': None, 'traceback': '  File "/home/runner/workspace/.pythonlibs/lib/python3.11/site-packages/flask/app.py", line 867, in full_dispatch_request\n    rv = self.dispatch_request()\n         ^^^^^^^^^^^^^^^^^^^^^^^\n  File "/home/runner/workspace/.pythonlibs/lib/python3.11/site-packages/flask/app.py", line 852, in dispatch_request\n    return self.ensure_sync(self.view_functions[rule.endpoint])(**view_args)\n           ^^^^^^^^^^^^^^^^^^^^^^^^^^^^^^^^^^^^^^^^^^^^^^^^^^^^^^^^^^^^^^^^^\n  File "/home/runner/workspace/.pythonlibs/lib/python3.11/site-packages/flask_login/utils.py", line 290, in decorated_view\n    return current_app.ensure_sync(func)(*args, **kwargs)\n           ^^^^^^^^^^^^^^^^^^^^^^^^^^^^^^^^^^^^^^^^^^^^^^\n  File "/home/runner/workspace/app.py", line 598, in welcome\n    Site.updated_at.desc()).all()\n                            ^^^^^\n  File "/home/runner/workspace/.pythonlibs/lib/python3.11/site-packages/sqlalchemy/orm/query.py", line 2704, in all\n    return self._iter().all()  # type: ignore\n           ^^^^^^^^^^^^\n  File "/home/runner/workspace/.pythonlibs/lib/python3.11/site-packages/sqlalchemy/orm/query.py", line 2858, in _iter\n    result: Union[ScalarResult[_T], Result[_T]] = self.session.execute(\n                                                  ^^^^^^^^^^^^^^^^^^^^^\n  File "/home/runner/workspace/.pythonlibs/lib/python3.11/site-packages/sqlalchemy/orm/session.py", line 2365, in execute\n    return self._execute_internal(\n           ^^^^^^^^^^^^^^^^^^^^^^^\n  File "/home/runner/workspace/.pythonlibs/lib/python3.11/site-packages/sqlalchemy/orm/session.py", line 2251, in _execute_internal\n    result: Result[Any] = compile_state_cls.orm_execute_statement(\n                          ^^^^^^^^^^^^^^^^^^^^^^^^^^^^^^^^^^^^^^^^\n  File "/home/runner/workspace/.pythonlibs/lib/python3.11/site-packages/sqlalchemy/orm/context.py", line 306, in orm_execute_statement\n    result = conn.execute(\n             ^^^^^^^^^^^^^\n  File "/home/runner/workspace/.pythonlibs/lib/python3.11/site-packages/sqlalchemy/engine/base.py", line 1416, in execute\n    return meth(\n           ^^^^^\n  File "/home/runner/workspace/.pythonlibs/lib/python3.11/site-packages/sqlalchemy/sql/elements.py", line 523, in _execute_on_connection\n    return connection._execute_clauseelement(\n           ^^^^^^^^^^^^^^^^^^^^^^^^^^^^^^^^^^\n  File "/home/runner/workspace/.pythonlibs/lib/python3.11/site-packages/sqlalchemy/engine/base.py", line 1638, in _execute_clauseelement\n    ret = self._execute_context(\n          ^^^^^^^^^^^^^^^^^^^^^^\n  File "/home/runner/workspace/.pythonlibs/lib/python3.11/site-packages/sqlalchemy/engine/base.py", line 1843, in _execute_context\n    return self._exec_single_context(\n           ^^^^^^^^^^^^^^^^^^^^^^^^^^\n  File "/home/runner/workspace/.pythonlibs/lib/python3.11/site-packages/sqlalchemy/engine/base.py", line 1983, in _exec_single_context\n    self._handle_dbapi_exception(\n  File "/home/runner/workspace/.pythonlibs/lib/python3.11/site-packages/sqlalchemy/engine/base.py", line 2352, in _handle_dbapi_exception\n    raise sqlalchemy_exception.with_traceback(exc_info[2]) from e\n  File "/home/runner/workspace/.pythonlibs/lib/python3.11/site-packages/sqlalchemy/engine/base.py", line 1964, in _exec_single_context\n    self.dialect.do_execute(\n  File "/home/runner/workspace/.pythonlibs/lib/python3.11/site-packages/sqlalchemy/engine/default.py", line 945, in do_execute\n    cursor.execute(statement, parameters)\n', 'suggestions': ['Verify database connection settings', 'Check for invalid queries or constraints', 'Ensure all required fields are provided']}
[2025-04-15 18:07:25] [INFO] 172.31.128.46 - - [15/Apr/2025 18:07:25] "GET /welcome HTTP/1.1" 0 -
[2025-04-15 18:07:25,452] [ERROR] Unhandled Exception: {'error_type': 'Database Error', 'error_message': "(psycopg2.errors.UndefinedColumn) column site.pixi_content does not exist\nLINE 1: ...tent, site.python_content AS site_python_content, site.pixi_...\n                                                             ^\n\n[SQL: SELECT site.id AS site_id, site.name AS site_name, site.slug AS site_slug, site.site_type AS site_site_type, site.html_content AS site_html_content, site.python_content AS site_python_content, site.pixi_content AS site_pixi_content, site.is_public AS site_is_public, site.created_at AS site_created_at, site.updated_at AS site_updated_at, site.user_id AS site_user_id, site.view_count AS site_view_count, site.analytics_enabled AS site_analytics_enabled \nFROM site \nWHERE site.user_id = %(user_id_1)s ORDER BY site.updated_at DESC]\n[parameters: {'user_id_1': 149}]\n(Background on this error at: https://sqlalche.me/e/20/f405)", 'error_details': None, 'file_name': None, 'line_number': None, 'code_snippet': None, 'traceback': '  File "/home/runner/workspace/.pythonlibs/lib/python3.11/site-packages/flask/app.py", line 867, in full_dispatch_request\n    rv = self.dispatch_request()\n         ^^^^^^^^^^^^^^^^^^^^^^^\n  File "/home/runner/workspace/.pythonlibs/lib/python3.11/site-packages/flask/app.py", line 852, in dispatch_request\n    return self.ensure_sync(self.view_functions[rule.endpoint])(**view_args)\n           ^^^^^^^^^^^^^^^^^^^^^^^^^^^^^^^^^^^^^^^^^^^^^^^^^^^^^^^^^^^^^^^^^\n  File "/home/runner/workspace/.pythonlibs/lib/python3.11/site-packages/flask_login/utils.py", line 290, in decorated_view\n    return current_app.ensure_sync(func)(*args, **kwargs)\n           ^^^^^^^^^^^^^^^^^^^^^^^^^^^^^^^^^^^^^^^^^^^^^^\n  File "/home/runner/workspace/app.py", line 598, in welcome\n    Site.updated_at.desc()).all()\n                            ^^^^^\n  File "/home/runner/workspace/.pythonlibs/lib/python3.11/site-packages/sqlalchemy/orm/query.py", line 2704, in all\n    return self._iter().all()  # type: ignore\n           ^^^^^^^^^^^^\n  File "/home/runner/workspace/.pythonlibs/lib/python3.11/site-packages/sqlalchemy/orm/query.py", line 2858, in _iter\n    result: Union[ScalarResult[_T], Result[_T]] = self.session.execute(\n                                                  ^^^^^^^^^^^^^^^^^^^^^\n  File "/home/runner/workspace/.pythonlibs/lib/python3.11/site-packages/sqlalchemy/orm/session.py", line 2365, in execute\n    return self._execute_internal(\n           ^^^^^^^^^^^^^^^^^^^^^^^\n  File "/home/runner/workspace/.pythonlibs/lib/python3.11/site-packages/sqlalchemy/orm/session.py", line 2251, in _execute_internal\n    result: Result[Any] = compile_state_cls.orm_execute_statement(\n                          ^^^^^^^^^^^^^^^^^^^^^^^^^^^^^^^^^^^^^^^^\n  File "/home/runner/workspace/.pythonlibs/lib/python3.11/site-packages/sqlalchemy/orm/context.py", line 306, in orm_execute_statement\n    result = conn.execute(\n             ^^^^^^^^^^^^^\n  File "/home/runner/workspace/.pythonlibs/lib/python3.11/site-packages/sqlalchemy/engine/base.py", line 1416, in execute\n    return meth(\n           ^^^^^\n  File "/home/runner/workspace/.pythonlibs/lib/python3.11/site-packages/sqlalchemy/sql/elements.py", line 523, in _execute_on_connection\n    return connection._execute_clauseelement(\n           ^^^^^^^^^^^^^^^^^^^^^^^^^^^^^^^^^^\n  File "/home/runner/workspace/.pythonlibs/lib/python3.11/site-packages/sqlalchemy/engine/base.py", line 1638, in _execute_clauseelement\n    ret = self._execute_context(\n          ^^^^^^^^^^^^^^^^^^^^^^\n  File "/home/runner/workspace/.pythonlibs/lib/python3.11/site-packages/sqlalchemy/engine/base.py", line 1843, in _execute_context\n    return self._exec_single_context(\n           ^^^^^^^^^^^^^^^^^^^^^^^^^^\n  File "/home/runner/workspace/.pythonlibs/lib/python3.11/site-packages/sqlalchemy/engine/base.py", line 1983, in _exec_single_context\n    self._handle_dbapi_exception(\n  File "/home/runner/workspace/.pythonlibs/lib/python3.11/site-packages/sqlalchemy/engine/base.py", line 2352, in _handle_dbapi_exception\n    raise sqlalchemy_exception.with_traceback(exc_info[2]) from e\n  File "/home/runner/workspace/.pythonlibs/lib/python3.11/site-packages/sqlalchemy/engine/base.py", line 1964, in _exec_single_context\n    self.dialect.do_execute(\n  File "/home/runner/workspace/.pythonlibs/lib/python3.11/site-packages/sqlalchemy/engine/default.py", line 945, in do_execute\n    cursor.execute(statement, parameters)\n', 'suggestions': ['Verify database connection settings', 'Check for invalid queries or constraints', 'Ensure all required fields are provided']}
[2025-04-15 18:07:25] [ERROR] Unhandled Exception: {'error_type': 'Database Error', 'error_message': "(psycopg2.errors.UndefinedColumn) column site.pixi_content does not exist\nLINE 1: ...tent, site.python_content AS site_python_content, site.pixi_...\n                                                             ^\n\n[SQL: SELECT site.id AS site_id, site.name AS site_name, site.slug AS site_slug, site.site_type AS site_site_type, site.html_content AS site_html_content, site.python_content AS site_python_content, site.pixi_content AS site_pixi_content, site.is_public AS site_is_public, site.created_at AS site_created_at, site.updated_at AS site_updated_at, site.user_id AS site_user_id, site.view_count AS site_view_count, site.analytics_enabled AS site_analytics_enabled \nFROM site \nWHERE site.user_id = %(user_id_1)s ORDER BY site.updated_at DESC]\n[parameters: {'user_id_1': 149}]\n(Background on this error at: https://sqlalche.me/e/20/f405)", 'error_details': None, 'file_name': None, 'line_number': None, 'code_snippet': None, 'traceback': '  File "/home/runner/workspace/.pythonlibs/lib/python3.11/site-packages/flask/app.py", line 867, in full_dispatch_request\n    rv = self.dispatch_request()\n         ^^^^^^^^^^^^^^^^^^^^^^^\n  File "/home/runner/workspace/.pythonlibs/lib/python3.11/site-packages/flask/app.py", line 852, in dispatch_request\n    return self.ensure_sync(self.view_functions[rule.endpoint])(**view_args)\n           ^^^^^^^^^^^^^^^^^^^^^^^^^^^^^^^^^^^^^^^^^^^^^^^^^^^^^^^^^^^^^^^^^\n  File "/home/runner/workspace/.pythonlibs/lib/python3.11/site-packages/flask_login/utils.py", line 290, in decorated_view\n    return current_app.ensure_sync(func)(*args, **kwargs)\n           ^^^^^^^^^^^^^^^^^^^^^^^^^^^^^^^^^^^^^^^^^^^^^^\n  File "/home/runner/workspace/app.py", line 598, in welcome\n    Site.updated_at.desc()).all()\n                            ^^^^^\n  File "/home/runner/workspace/.pythonlibs/lib/python3.11/site-packages/sqlalchemy/orm/query.py", line 2704, in all\n    return self._iter().all()  # type: ignore\n           ^^^^^^^^^^^^\n  File "/home/runner/workspace/.pythonlibs/lib/python3.11/site-packages/sqlalchemy/orm/query.py", line 2858, in _iter\n    result: Union[ScalarResult[_T], Result[_T]] = self.session.execute(\n                                                  ^^^^^^^^^^^^^^^^^^^^^\n  File "/home/runner/workspace/.pythonlibs/lib/python3.11/site-packages/sqlalchemy/orm/session.py", line 2365, in execute\n    return self._execute_internal(\n           ^^^^^^^^^^^^^^^^^^^^^^^\n  File "/home/runner/workspace/.pythonlibs/lib/python3.11/site-packages/sqlalchemy/orm/session.py", line 2251, in _execute_internal\n    result: Result[Any] = compile_state_cls.orm_execute_statement(\n                          ^^^^^^^^^^^^^^^^^^^^^^^^^^^^^^^^^^^^^^^^\n  File "/home/runner/workspace/.pythonlibs/lib/python3.11/site-packages/sqlalchemy/orm/context.py", line 306, in orm_execute_statement\n    result = conn.execute(\n             ^^^^^^^^^^^^^\n  File "/home/runner/workspace/.pythonlibs/lib/python3.11/site-packages/sqlalchemy/engine/base.py", line 1416, in execute\n    return meth(\n           ^^^^^\n  File "/home/runner/workspace/.pythonlibs/lib/python3.11/site-packages/sqlalchemy/sql/elements.py", line 523, in _execute_on_connection\n    return connection._execute_clauseelement(\n           ^^^^^^^^^^^^^^^^^^^^^^^^^^^^^^^^^^\n  File "/home/runner/workspace/.pythonlibs/lib/python3.11/site-packages/sqlalchemy/engine/base.py", line 1638, in _execute_clauseelement\n    ret = self._execute_context(\n          ^^^^^^^^^^^^^^^^^^^^^^\n  File "/home/runner/workspace/.pythonlibs/lib/python3.11/site-packages/sqlalchemy/engine/base.py", line 1843, in _execute_context\n    return self._exec_single_context(\n           ^^^^^^^^^^^^^^^^^^^^^^^^^^\n  File "/home/runner/workspace/.pythonlibs/lib/python3.11/site-packages/sqlalchemy/engine/base.py", line 1983, in _exec_single_context\n    self._handle_dbapi_exception(\n  File "/home/runner/workspace/.pythonlibs/lib/python3.11/site-packages/sqlalchemy/engine/base.py", line 2352, in _handle_dbapi_exception\n    raise sqlalchemy_exception.with_traceback(exc_info[2]) from e\n  File "/home/runner/workspace/.pythonlibs/lib/python3.11/site-packages/sqlalchemy/engine/base.py", line 1964, in _exec_single_context\n    self.dialect.do_execute(\n  File "/home/runner/workspace/.pythonlibs/lib/python3.11/site-packages/sqlalchemy/engine/default.py", line 945, in do_execute\n    cursor.execute(statement, parameters)\n', 'suggestions': ['Verify database connection settings', 'Check for invalid queries or constraints', 'Ensure all required fields are provided']}
[2025-04-15 18:07:25] [INFO] 172.31.128.46 - - [15/Apr/2025 18:07:25] "GET /welcome HTTP/1.1" 0 -
[2025-04-15 18:07:28] [INFO] 172.31.128.46 - - [15/Apr/2025 18:07:28] "GET / HTTP/1.1" 200 -
[2025-04-15 18:07:28] [INFO] 172.31.128.46 - - [15/Apr/2025 18:07:28] "GET /static/css/style.css HTTP/1.1" 304 -
[2025-04-15 18:07:28] [INFO] 172.31.128.46 - - [15/Apr/2025 18:07:28] "GET /static/images/flag-orpheus-left.svg HTTP/1.1" 304 -
[2025-04-15 18:07:28] [INFO] 172.31.128.46 - - [15/Apr/2025 18:07:28] "GET /static/images/logo-rounded.png HTTP/1.1" 304 -
[2025-04-15 18:07:29] [INFO] 172.31.128.46 - - [15/Apr/2025 18:07:29] "GET /static/js/main.js HTTP/1.1" 304 -
[2025-04-15 18:07:29] [INFO] 172.31.128.46 - - [15/Apr/2025 18:07:29] "GET /static/images/favicon.ico HTTP/1.1" 304 -
[2025-04-15 18:07:30,555] [ERROR] Unhandled Exception: {'error_type': 'Database Error', 'error_message': "(psycopg2.errors.UndefinedColumn) column site.pixi_content does not exist\nLINE 1: ...tent, site.python_content AS site_python_content, site.pixi_...\n                                                             ^\n\n[SQL: SELECT site.id AS site_id, site.name AS site_name, site.slug AS site_slug, site.site_type AS site_site_type, site.html_content AS site_html_content, site.python_content AS site_python_content, site.pixi_content AS site_pixi_content, site.is_public AS site_is_public, site.created_at AS site_created_at, site.updated_at AS site_updated_at, site.user_id AS site_user_id, site.view_count AS site_view_count, site.analytics_enabled AS site_analytics_enabled \nFROM site \nWHERE site.user_id = %(user_id_1)s ORDER BY site.updated_at DESC]\n[parameters: {'user_id_1': 149}]\n(Background on this error at: https://sqlalche.me/e/20/f405)", 'error_details': None, 'file_name': None, 'line_number': None, 'code_snippet': None, 'traceback': '  File "/home/runner/workspace/.pythonlibs/lib/python3.11/site-packages/flask/app.py", line 867, in full_dispatch_request\n    rv = self.dispatch_request()\n         ^^^^^^^^^^^^^^^^^^^^^^^\n  File "/home/runner/workspace/.pythonlibs/lib/python3.11/site-packages/flask/app.py", line 852, in dispatch_request\n    return self.ensure_sync(self.view_functions[rule.endpoint])(**view_args)\n           ^^^^^^^^^^^^^^^^^^^^^^^^^^^^^^^^^^^^^^^^^^^^^^^^^^^^^^^^^^^^^^^^^\n  File "/home/runner/workspace/.pythonlibs/lib/python3.11/site-packages/flask_login/utils.py", line 290, in decorated_view\n    return current_app.ensure_sync(func)(*args, **kwargs)\n           ^^^^^^^^^^^^^^^^^^^^^^^^^^^^^^^^^^^^^^^^^^^^^^\n  File "/home/runner/workspace/app.py", line 598, in welcome\n    Site.updated_at.desc()).all()\n                            ^^^^^\n  File "/home/runner/workspace/.pythonlibs/lib/python3.11/site-packages/sqlalchemy/orm/query.py", line 2704, in all\n    return self._iter().all()  # type: ignore\n           ^^^^^^^^^^^^\n  File "/home/runner/workspace/.pythonlibs/lib/python3.11/site-packages/sqlalchemy/orm/query.py", line 2858, in _iter\n    result: Union[ScalarResult[_T], Result[_T]] = self.session.execute(\n                                                  ^^^^^^^^^^^^^^^^^^^^^\n  File "/home/runner/workspace/.pythonlibs/lib/python3.11/site-packages/sqlalchemy/orm/session.py", line 2365, in execute\n    return self._execute_internal(\n           ^^^^^^^^^^^^^^^^^^^^^^^\n  File "/home/runner/workspace/.pythonlibs/lib/python3.11/site-packages/sqlalchemy/orm/session.py", line 2251, in _execute_internal\n    result: Result[Any] = compile_state_cls.orm_execute_statement(\n                          ^^^^^^^^^^^^^^^^^^^^^^^^^^^^^^^^^^^^^^^^\n  File "/home/runner/workspace/.pythonlibs/lib/python3.11/site-packages/sqlalchemy/orm/context.py", line 306, in orm_execute_statement\n    result = conn.execute(\n             ^^^^^^^^^^^^^\n  File "/home/runner/workspace/.pythonlibs/lib/python3.11/site-packages/sqlalchemy/engine/base.py", line 1416, in execute\n    return meth(\n           ^^^^^\n  File "/home/runner/workspace/.pythonlibs/lib/python3.11/site-packages/sqlalchemy/sql/elements.py", line 523, in _execute_on_connection\n    return connection._execute_clauseelement(\n           ^^^^^^^^^^^^^^^^^^^^^^^^^^^^^^^^^^\n  File "/home/runner/workspace/.pythonlibs/lib/python3.11/site-packages/sqlalchemy/engine/base.py", line 1638, in _execute_clauseelement\n    ret = self._execute_context(\n          ^^^^^^^^^^^^^^^^^^^^^^\n  File "/home/runner/workspace/.pythonlibs/lib/python3.11/site-packages/sqlalchemy/engine/base.py", line 1843, in _execute_context\n    return self._exec_single_context(\n           ^^^^^^^^^^^^^^^^^^^^^^^^^^\n  File "/home/runner/workspace/.pythonlibs/lib/python3.11/site-packages/sqlalchemy/engine/base.py", line 1983, in _exec_single_context\n    self._handle_dbapi_exception(\n  File "/home/runner/workspace/.pythonlibs/lib/python3.11/site-packages/sqlalchemy/engine/base.py", line 2352, in _handle_dbapi_exception\n    raise sqlalchemy_exception.with_traceback(exc_info[2]) from e\n  File "/home/runner/workspace/.pythonlibs/lib/python3.11/site-packages/sqlalchemy/engine/base.py", line 1964, in _exec_single_context\n    self.dialect.do_execute(\n  File "/home/runner/workspace/.pythonlibs/lib/python3.11/site-packages/sqlalchemy/engine/default.py", line 945, in do_execute\n    cursor.execute(statement, parameters)\n', 'suggestions': ['Verify database connection settings', 'Check for invalid queries or constraints', 'Ensure all required fields are provided']}
[2025-04-15 18:07:30] [ERROR] Unhandled Exception: {'error_type': 'Database Error', 'error_message': "(psycopg2.errors.UndefinedColumn) column site.pixi_content does not exist\nLINE 1: ...tent, site.python_content AS site_python_content, site.pixi_...\n                                                             ^\n\n[SQL: SELECT site.id AS site_id, site.name AS site_name, site.slug AS site_slug, site.site_type AS site_site_type, site.html_content AS site_html_content, site.python_content AS site_python_content, site.pixi_content AS site_pixi_content, site.is_public AS site_is_public, site.created_at AS site_created_at, site.updated_at AS site_updated_at, site.user_id AS site_user_id, site.view_count AS site_view_count, site.analytics_enabled AS site_analytics_enabled \nFROM site \nWHERE site.user_id = %(user_id_1)s ORDER BY site.updated_at DESC]\n[parameters: {'user_id_1': 149}]\n(Background on this error at: https://sqlalche.me/e/20/f405)", 'error_details': None, 'file_name': None, 'line_number': None, 'code_snippet': None, 'traceback': '  File "/home/runner/workspace/.pythonlibs/lib/python3.11/site-packages/flask/app.py", line 867, in full_dispatch_request\n    rv = self.dispatch_request()\n         ^^^^^^^^^^^^^^^^^^^^^^^\n  File "/home/runner/workspace/.pythonlibs/lib/python3.11/site-packages/flask/app.py", line 852, in dispatch_request\n    return self.ensure_sync(self.view_functions[rule.endpoint])(**view_args)\n           ^^^^^^^^^^^^^^^^^^^^^^^^^^^^^^^^^^^^^^^^^^^^^^^^^^^^^^^^^^^^^^^^^\n  File "/home/runner/workspace/.pythonlibs/lib/python3.11/site-packages/flask_login/utils.py", line 290, in decorated_view\n    return current_app.ensure_sync(func)(*args, **kwargs)\n           ^^^^^^^^^^^^^^^^^^^^^^^^^^^^^^^^^^^^^^^^^^^^^^\n  File "/home/runner/workspace/app.py", line 598, in welcome\n    Site.updated_at.desc()).all()\n                            ^^^^^\n  File "/home/runner/workspace/.pythonlibs/lib/python3.11/site-packages/sqlalchemy/orm/query.py", line 2704, in all\n    return self._iter().all()  # type: ignore\n           ^^^^^^^^^^^^\n  File "/home/runner/workspace/.pythonlibs/lib/python3.11/site-packages/sqlalchemy/orm/query.py", line 2858, in _iter\n    result: Union[ScalarResult[_T], Result[_T]] = self.session.execute(\n                                                  ^^^^^^^^^^^^^^^^^^^^^\n  File "/home/runner/workspace/.pythonlibs/lib/python3.11/site-packages/sqlalchemy/orm/session.py", line 2365, in execute\n    return self._execute_internal(\n           ^^^^^^^^^^^^^^^^^^^^^^^\n  File "/home/runner/workspace/.pythonlibs/lib/python3.11/site-packages/sqlalchemy/orm/session.py", line 2251, in _execute_internal\n    result: Result[Any] = compile_state_cls.orm_execute_statement(\n                          ^^^^^^^^^^^^^^^^^^^^^^^^^^^^^^^^^^^^^^^^\n  File "/home/runner/workspace/.pythonlibs/lib/python3.11/site-packages/sqlalchemy/orm/context.py", line 306, in orm_execute_statement\n    result = conn.execute(\n             ^^^^^^^^^^^^^\n  File "/home/runner/workspace/.pythonlibs/lib/python3.11/site-packages/sqlalchemy/engine/base.py", line 1416, in execute\n    return meth(\n           ^^^^^\n  File "/home/runner/workspace/.pythonlibs/lib/python3.11/site-packages/sqlalchemy/sql/elements.py", line 523, in _execute_on_connection\n    return connection._execute_clauseelement(\n           ^^^^^^^^^^^^^^^^^^^^^^^^^^^^^^^^^^\n  File "/home/runner/workspace/.pythonlibs/lib/python3.11/site-packages/sqlalchemy/engine/base.py", line 1638, in _execute_clauseelement\n    ret = self._execute_context(\n          ^^^^^^^^^^^^^^^^^^^^^^\n  File "/home/runner/workspace/.pythonlibs/lib/python3.11/site-packages/sqlalchemy/engine/base.py", line 1843, in _execute_context\n    return self._exec_single_context(\n           ^^^^^^^^^^^^^^^^^^^^^^^^^^\n  File "/home/runner/workspace/.pythonlibs/lib/python3.11/site-packages/sqlalchemy/engine/base.py", line 1983, in _exec_single_context\n    self._handle_dbapi_exception(\n  File "/home/runner/workspace/.pythonlibs/lib/python3.11/site-packages/sqlalchemy/engine/base.py", line 2352, in _handle_dbapi_exception\n    raise sqlalchemy_exception.with_traceback(exc_info[2]) from e\n  File "/home/runner/workspace/.pythonlibs/lib/python3.11/site-packages/sqlalchemy/engine/base.py", line 1964, in _exec_single_context\n    self.dialect.do_execute(\n  File "/home/runner/workspace/.pythonlibs/lib/python3.11/site-packages/sqlalchemy/engine/default.py", line 945, in do_execute\n    cursor.execute(statement, parameters)\n', 'suggestions': ['Verify database connection settings', 'Check for invalid queries or constraints', 'Ensure all required fields are provided']}
[2025-04-15 18:07:30] [INFO] 172.31.128.46 - - [15/Apr/2025 18:07:30] "GET /welcome HTTP/1.1" 0 -
[2025-04-15 18:07:30,813] [ERROR] Unhandled Exception: {'error_type': 'Database Error', 'error_message': "(psycopg2.errors.UndefinedColumn) column site.pixi_content does not exist\nLINE 1: ...tent, site.python_content AS site_python_content, site.pixi_...\n                                                             ^\n\n[SQL: SELECT site.id AS site_id, site.name AS site_name, site.slug AS site_slug, site.site_type AS site_site_type, site.html_content AS site_html_content, site.python_content AS site_python_content, site.pixi_content AS site_pixi_content, site.is_public AS site_is_public, site.created_at AS site_created_at, site.updated_at AS site_updated_at, site.user_id AS site_user_id, site.view_count AS site_view_count, site.analytics_enabled AS site_analytics_enabled \nFROM site \nWHERE site.user_id = %(user_id_1)s ORDER BY site.updated_at DESC]\n[parameters: {'user_id_1': 149}]\n(Background on this error at: https://sqlalche.me/e/20/f405)", 'error_details': None, 'file_name': None, 'line_number': None, 'code_snippet': None, 'traceback': '  File "/home/runner/workspace/.pythonlibs/lib/python3.11/site-packages/flask/app.py", line 867, in full_dispatch_request\n    rv = self.dispatch_request()\n         ^^^^^^^^^^^^^^^^^^^^^^^\n  File "/home/runner/workspace/.pythonlibs/lib/python3.11/site-packages/flask/app.py", line 852, in dispatch_request\n    return self.ensure_sync(self.view_functions[rule.endpoint])(**view_args)\n           ^^^^^^^^^^^^^^^^^^^^^^^^^^^^^^^^^^^^^^^^^^^^^^^^^^^^^^^^^^^^^^^^^\n  File "/home/runner/workspace/.pythonlibs/lib/python3.11/site-packages/flask_login/utils.py", line 290, in decorated_view\n    return current_app.ensure_sync(func)(*args, **kwargs)\n           ^^^^^^^^^^^^^^^^^^^^^^^^^^^^^^^^^^^^^^^^^^^^^^\n  File "/home/runner/workspace/app.py", line 598, in welcome\n    Site.updated_at.desc()).all()\n                            ^^^^^\n  File "/home/runner/workspace/.pythonlibs/lib/python3.11/site-packages/sqlalchemy/orm/query.py", line 2704, in all\n    return self._iter().all()  # type: ignore\n           ^^^^^^^^^^^^\n  File "/home/runner/workspace/.pythonlibs/lib/python3.11/site-packages/sqlalchemy/orm/query.py", line 2858, in _iter\n    result: Union[ScalarResult[_T], Result[_T]] = self.session.execute(\n                                                  ^^^^^^^^^^^^^^^^^^^^^\n  File "/home/runner/workspace/.pythonlibs/lib/python3.11/site-packages/sqlalchemy/orm/session.py", line 2365, in execute\n    return self._execute_internal(\n           ^^^^^^^^^^^^^^^^^^^^^^^\n  File "/home/runner/workspace/.pythonlibs/lib/python3.11/site-packages/sqlalchemy/orm/session.py", line 2251, in _execute_internal\n    result: Result[Any] = compile_state_cls.orm_execute_statement(\n                          ^^^^^^^^^^^^^^^^^^^^^^^^^^^^^^^^^^^^^^^^\n  File "/home/runner/workspace/.pythonlibs/lib/python3.11/site-packages/sqlalchemy/orm/context.py", line 306, in orm_execute_statement\n    result = conn.execute(\n             ^^^^^^^^^^^^^\n  File "/home/runner/workspace/.pythonlibs/lib/python3.11/site-packages/sqlalchemy/engine/base.py", line 1416, in execute\n    return meth(\n           ^^^^^\n  File "/home/runner/workspace/.pythonlibs/lib/python3.11/site-packages/sqlalchemy/sql/elements.py", line 523, in _execute_on_connection\n    return connection._execute_clauseelement(\n           ^^^^^^^^^^^^^^^^^^^^^^^^^^^^^^^^^^\n  File "/home/runner/workspace/.pythonlibs/lib/python3.11/site-packages/sqlalchemy/engine/base.py", line 1638, in _execute_clauseelement\n    ret = self._execute_context(\n          ^^^^^^^^^^^^^^^^^^^^^^\n  File "/home/runner/workspace/.pythonlibs/lib/python3.11/site-packages/sqlalchemy/engine/base.py", line 1843, in _execute_context\n    return self._exec_single_context(\n           ^^^^^^^^^^^^^^^^^^^^^^^^^^\n  File "/home/runner/workspace/.pythonlibs/lib/python3.11/site-packages/sqlalchemy/engine/base.py", line 1983, in _exec_single_context\n    self._handle_dbapi_exception(\n  File "/home/runner/workspace/.pythonlibs/lib/python3.11/site-packages/sqlalchemy/engine/base.py", line 2352, in _handle_dbapi_exception\n    raise sqlalchemy_exception.with_traceback(exc_info[2]) from e\n  File "/home/runner/workspace/.pythonlibs/lib/python3.11/site-packages/sqlalchemy/engine/base.py", line 1964, in _exec_single_context\n    self.dialect.do_execute(\n  File "/home/runner/workspace/.pythonlibs/lib/python3.11/site-packages/sqlalchemy/engine/default.py", line 945, in do_execute\n    cursor.execute(statement, parameters)\n', 'suggestions': ['Verify database connection settings', 'Check for invalid queries or constraints', 'Ensure all required fields are provided']}
[2025-04-15 18:07:30] [ERROR] Unhandled Exception: {'error_type': 'Database Error', 'error_message': "(psycopg2.errors.UndefinedColumn) column site.pixi_content does not exist\nLINE 1: ...tent, site.python_content AS site_python_content, site.pixi_...\n                                                             ^\n\n[SQL: SELECT site.id AS site_id, site.name AS site_name, site.slug AS site_slug, site.site_type AS site_site_type, site.html_content AS site_html_content, site.python_content AS site_python_content, site.pixi_content AS site_pixi_content, site.is_public AS site_is_public, site.created_at AS site_created_at, site.updated_at AS site_updated_at, site.user_id AS site_user_id, site.view_count AS site_view_count, site.analytics_enabled AS site_analytics_enabled \nFROM site \nWHERE site.user_id = %(user_id_1)s ORDER BY site.updated_at DESC]\n[parameters: {'user_id_1': 149}]\n(Background on this error at: https://sqlalche.me/e/20/f405)", 'error_details': None, 'file_name': None, 'line_number': None, 'code_snippet': None, 'traceback': '  File "/home/runner/workspace/.pythonlibs/lib/python3.11/site-packages/flask/app.py", line 867, in full_dispatch_request\n    rv = self.dispatch_request()\n         ^^^^^^^^^^^^^^^^^^^^^^^\n  File "/home/runner/workspace/.pythonlibs/lib/python3.11/site-packages/flask/app.py", line 852, in dispatch_request\n    return self.ensure_sync(self.view_functions[rule.endpoint])(**view_args)\n           ^^^^^^^^^^^^^^^^^^^^^^^^^^^^^^^^^^^^^^^^^^^^^^^^^^^^^^^^^^^^^^^^^\n  File "/home/runner/workspace/.pythonlibs/lib/python3.11/site-packages/flask_login/utils.py", line 290, in decorated_view\n    return current_app.ensure_sync(func)(*args, **kwargs)\n           ^^^^^^^^^^^^^^^^^^^^^^^^^^^^^^^^^^^^^^^^^^^^^^\n  File "/home/runner/workspace/app.py", line 598, in welcome\n    Site.updated_at.desc()).all()\n                            ^^^^^\n  File "/home/runner/workspace/.pythonlibs/lib/python3.11/site-packages/sqlalchemy/orm/query.py", line 2704, in all\n    return self._iter().all()  # type: ignore\n           ^^^^^^^^^^^^\n  File "/home/runner/workspace/.pythonlibs/lib/python3.11/site-packages/sqlalchemy/orm/query.py", line 2858, in _iter\n    result: Union[ScalarResult[_T], Result[_T]] = self.session.execute(\n                                                  ^^^^^^^^^^^^^^^^^^^^^\n  File "/home/runner/workspace/.pythonlibs/lib/python3.11/site-packages/sqlalchemy/orm/session.py", line 2365, in execute\n    return self._execute_internal(\n           ^^^^^^^^^^^^^^^^^^^^^^^\n  File "/home/runner/workspace/.pythonlibs/lib/python3.11/site-packages/sqlalchemy/orm/session.py", line 2251, in _execute_internal\n    result: Result[Any] = compile_state_cls.orm_execute_statement(\n                          ^^^^^^^^^^^^^^^^^^^^^^^^^^^^^^^^^^^^^^^^\n  File "/home/runner/workspace/.pythonlibs/lib/python3.11/site-packages/sqlalchemy/orm/context.py", line 306, in orm_execute_statement\n    result = conn.execute(\n             ^^^^^^^^^^^^^\n  File "/home/runner/workspace/.pythonlibs/lib/python3.11/site-packages/sqlalchemy/engine/base.py", line 1416, in execute\n    return meth(\n           ^^^^^\n  File "/home/runner/workspace/.pythonlibs/lib/python3.11/site-packages/sqlalchemy/sql/elements.py", line 523, in _execute_on_connection\n    return connection._execute_clauseelement(\n           ^^^^^^^^^^^^^^^^^^^^^^^^^^^^^^^^^^\n  File "/home/runner/workspace/.pythonlibs/lib/python3.11/site-packages/sqlalchemy/engine/base.py", line 1638, in _execute_clauseelement\n    ret = self._execute_context(\n          ^^^^^^^^^^^^^^^^^^^^^^\n  File "/home/runner/workspace/.pythonlibs/lib/python3.11/site-packages/sqlalchemy/engine/base.py", line 1843, in _execute_context\n    return self._exec_single_context(\n           ^^^^^^^^^^^^^^^^^^^^^^^^^^\n  File "/home/runner/workspace/.pythonlibs/lib/python3.11/site-packages/sqlalchemy/engine/base.py", line 1983, in _exec_single_context\n    self._handle_dbapi_exception(\n  File "/home/runner/workspace/.pythonlibs/lib/python3.11/site-packages/sqlalchemy/engine/base.py", line 2352, in _handle_dbapi_exception\n    raise sqlalchemy_exception.with_traceback(exc_info[2]) from e\n  File "/home/runner/workspace/.pythonlibs/lib/python3.11/site-packages/sqlalchemy/engine/base.py", line 1964, in _exec_single_context\n    self.dialect.do_execute(\n  File "/home/runner/workspace/.pythonlibs/lib/python3.11/site-packages/sqlalchemy/engine/default.py", line 945, in do_execute\n    cursor.execute(statement, parameters)\n', 'suggestions': ['Verify database connection settings', 'Check for invalid queries or constraints', 'Ensure all required fields are provided']}
[2025-04-15 18:07:30] [INFO] 172.31.128.46 - - [15/Apr/2025 18:07:30] "GET /welcome HTTP/1.1" 0 -
[2025-04-15 18:07:31,068] [ERROR] Unhandled Exception: {'error_type': 'Database Error', 'error_message': "(psycopg2.errors.UndefinedColumn) column site.pixi_content does not exist\nLINE 1: ...tent, site.python_content AS site_python_content, site.pixi_...\n                                                             ^\n\n[SQL: SELECT site.id AS site_id, site.name AS site_name, site.slug AS site_slug, site.site_type AS site_site_type, site.html_content AS site_html_content, site.python_content AS site_python_content, site.pixi_content AS site_pixi_content, site.is_public AS site_is_public, site.created_at AS site_created_at, site.updated_at AS site_updated_at, site.user_id AS site_user_id, site.view_count AS site_view_count, site.analytics_enabled AS site_analytics_enabled \nFROM site \nWHERE site.user_id = %(user_id_1)s ORDER BY site.updated_at DESC]\n[parameters: {'user_id_1': 149}]\n(Background on this error at: https://sqlalche.me/e/20/f405)", 'error_details': None, 'file_name': None, 'line_number': None, 'code_snippet': None, 'traceback': '  File "/home/runner/workspace/.pythonlibs/lib/python3.11/site-packages/flask/app.py", line 867, in full_dispatch_request\n    rv = self.dispatch_request()\n         ^^^^^^^^^^^^^^^^^^^^^^^\n  File "/home/runner/workspace/.pythonlibs/lib/python3.11/site-packages/flask/app.py", line 852, in dispatch_request\n    return self.ensure_sync(self.view_functions[rule.endpoint])(**view_args)\n           ^^^^^^^^^^^^^^^^^^^^^^^^^^^^^^^^^^^^^^^^^^^^^^^^^^^^^^^^^^^^^^^^^\n  File "/home/runner/workspace/.pythonlibs/lib/python3.11/site-packages/flask_login/utils.py", line 290, in decorated_view\n    return current_app.ensure_sync(func)(*args, **kwargs)\n           ^^^^^^^^^^^^^^^^^^^^^^^^^^^^^^^^^^^^^^^^^^^^^^\n  File "/home/runner/workspace/app.py", line 598, in welcome\n    Site.updated_at.desc()).all()\n                            ^^^^^\n  File "/home/runner/workspace/.pythonlibs/lib/python3.11/site-packages/sqlalchemy/orm/query.py", line 2704, in all\n    return self._iter().all()  # type: ignore\n           ^^^^^^^^^^^^\n  File "/home/runner/workspace/.pythonlibs/lib/python3.11/site-packages/sqlalchemy/orm/query.py", line 2858, in _iter\n    result: Union[ScalarResult[_T], Result[_T]] = self.session.execute(\n                                                  ^^^^^^^^^^^^^^^^^^^^^\n  File "/home/runner/workspace/.pythonlibs/lib/python3.11/site-packages/sqlalchemy/orm/session.py", line 2365, in execute\n    return self._execute_internal(\n           ^^^^^^^^^^^^^^^^^^^^^^^\n  File "/home/runner/workspace/.pythonlibs/lib/python3.11/site-packages/sqlalchemy/orm/session.py", line 2251, in _execute_internal\n    result: Result[Any] = compile_state_cls.orm_execute_statement(\n                          ^^^^^^^^^^^^^^^^^^^^^^^^^^^^^^^^^^^^^^^^\n  File "/home/runner/workspace/.pythonlibs/lib/python3.11/site-packages/sqlalchemy/orm/context.py", line 306, in orm_execute_statement\n    result = conn.execute(\n             ^^^^^^^^^^^^^\n  File "/home/runner/workspace/.pythonlibs/lib/python3.11/site-packages/sqlalchemy/engine/base.py", line 1416, in execute\n    return meth(\n           ^^^^^\n  File "/home/runner/workspace/.pythonlibs/lib/python3.11/site-packages/sqlalchemy/sql/elements.py", line 523, in _execute_on_connection\n    return connection._execute_clauseelement(\n           ^^^^^^^^^^^^^^^^^^^^^^^^^^^^^^^^^^\n  File "/home/runner/workspace/.pythonlibs/lib/python3.11/site-packages/sqlalchemy/engine/base.py", line 1638, in _execute_clauseelement\n    ret = self._execute_context(\n          ^^^^^^^^^^^^^^^^^^^^^^\n  File "/home/runner/workspace/.pythonlibs/lib/python3.11/site-packages/sqlalchemy/engine/base.py", line 1843, in _execute_context\n    return self._exec_single_context(\n           ^^^^^^^^^^^^^^^^^^^^^^^^^^\n  File "/home/runner/workspace/.pythonlibs/lib/python3.11/site-packages/sqlalchemy/engine/base.py", line 1983, in _exec_single_context\n    self._handle_dbapi_exception(\n  File "/home/runner/workspace/.pythonlibs/lib/python3.11/site-packages/sqlalchemy/engine/base.py", line 2352, in _handle_dbapi_exception\n    raise sqlalchemy_exception.with_traceback(exc_info[2]) from e\n  File "/home/runner/workspace/.pythonlibs/lib/python3.11/site-packages/sqlalchemy/engine/base.py", line 1964, in _exec_single_context\n    self.dialect.do_execute(\n  File "/home/runner/workspace/.pythonlibs/lib/python3.11/site-packages/sqlalchemy/engine/default.py", line 945, in do_execute\n    cursor.execute(statement, parameters)\n', 'suggestions': ['Verify database connection settings', 'Check for invalid queries or constraints', 'Ensure all required fields are provided']}
[2025-04-15 18:07:31] [ERROR] Unhandled Exception: {'error_type': 'Database Error', 'error_message': "(psycopg2.errors.UndefinedColumn) column site.pixi_content does not exist\nLINE 1: ...tent, site.python_content AS site_python_content, site.pixi_...\n                                                             ^\n\n[SQL: SELECT site.id AS site_id, site.name AS site_name, site.slug AS site_slug, site.site_type AS site_site_type, site.html_content AS site_html_content, site.python_content AS site_python_content, site.pixi_content AS site_pixi_content, site.is_public AS site_is_public, site.created_at AS site_created_at, site.updated_at AS site_updated_at, site.user_id AS site_user_id, site.view_count AS site_view_count, site.analytics_enabled AS site_analytics_enabled \nFROM site \nWHERE site.user_id = %(user_id_1)s ORDER BY site.updated_at DESC]\n[parameters: {'user_id_1': 149}]\n(Background on this error at: https://sqlalche.me/e/20/f405)", 'error_details': None, 'file_name': None, 'line_number': None, 'code_snippet': None, 'traceback': '  File "/home/runner/workspace/.pythonlibs/lib/python3.11/site-packages/flask/app.py", line 867, in full_dispatch_request\n    rv = self.dispatch_request()\n         ^^^^^^^^^^^^^^^^^^^^^^^\n  File "/home/runner/workspace/.pythonlibs/lib/python3.11/site-packages/flask/app.py", line 852, in dispatch_request\n    return self.ensure_sync(self.view_functions[rule.endpoint])(**view_args)\n           ^^^^^^^^^^^^^^^^^^^^^^^^^^^^^^^^^^^^^^^^^^^^^^^^^^^^^^^^^^^^^^^^^\n  File "/home/runner/workspace/.pythonlibs/lib/python3.11/site-packages/flask_login/utils.py", line 290, in decorated_view\n    return current_app.ensure_sync(func)(*args, **kwargs)\n           ^^^^^^^^^^^^^^^^^^^^^^^^^^^^^^^^^^^^^^^^^^^^^^\n  File "/home/runner/workspace/app.py", line 598, in welcome\n    Site.updated_at.desc()).all()\n                            ^^^^^\n  File "/home/runner/workspace/.pythonlibs/lib/python3.11/site-packages/sqlalchemy/orm/query.py", line 2704, in all\n    return self._iter().all()  # type: ignore\n           ^^^^^^^^^^^^\n  File "/home/runner/workspace/.pythonlibs/lib/python3.11/site-packages/sqlalchemy/orm/query.py", line 2858, in _iter\n    result: Union[ScalarResult[_T], Result[_T]] = self.session.execute(\n                                                  ^^^^^^^^^^^^^^^^^^^^^\n  File "/home/runner/workspace/.pythonlibs/lib/python3.11/site-packages/sqlalchemy/orm/session.py", line 2365, in execute\n    return self._execute_internal(\n           ^^^^^^^^^^^^^^^^^^^^^^^\n  File "/home/runner/workspace/.pythonlibs/lib/python3.11/site-packages/sqlalchemy/orm/session.py", line 2251, in _execute_internal\n    result: Result[Any] = compile_state_cls.orm_execute_statement(\n                          ^^^^^^^^^^^^^^^^^^^^^^^^^^^^^^^^^^^^^^^^\n  File "/home/runner/workspace/.pythonlibs/lib/python3.11/site-packages/sqlalchemy/orm/context.py", line 306, in orm_execute_statement\n    result = conn.execute(\n             ^^^^^^^^^^^^^\n  File "/home/runner/workspace/.pythonlibs/lib/python3.11/site-packages/sqlalchemy/engine/base.py", line 1416, in execute\n    return meth(\n           ^^^^^\n  File "/home/runner/workspace/.pythonlibs/lib/python3.11/site-packages/sqlalchemy/sql/elements.py", line 523, in _execute_on_connection\n    return connection._execute_clauseelement(\n           ^^^^^^^^^^^^^^^^^^^^^^^^^^^^^^^^^^\n  File "/home/runner/workspace/.pythonlibs/lib/python3.11/site-packages/sqlalchemy/engine/base.py", line 1638, in _execute_clauseelement\n    ret = self._execute_context(\n          ^^^^^^^^^^^^^^^^^^^^^^\n  File "/home/runner/workspace/.pythonlibs/lib/python3.11/site-packages/sqlalchemy/engine/base.py", line 1843, in _execute_context\n    return self._exec_single_context(\n           ^^^^^^^^^^^^^^^^^^^^^^^^^^\n  File "/home/runner/workspace/.pythonlibs/lib/python3.11/site-packages/sqlalchemy/engine/base.py", line 1983, in _exec_single_context\n    self._handle_dbapi_exception(\n  File "/home/runner/workspace/.pythonlibs/lib/python3.11/site-packages/sqlalchemy/engine/base.py", line 2352, in _handle_dbapi_exception\n    raise sqlalchemy_exception.with_traceback(exc_info[2]) from e\n  File "/home/runner/workspace/.pythonlibs/lib/python3.11/site-packages/sqlalchemy/engine/base.py", line 1964, in _exec_single_context\n    self.dialect.do_execute(\n  File "/home/runner/workspace/.pythonlibs/lib/python3.11/site-packages/sqlalchemy/engine/default.py", line 945, in do_execute\n    cursor.execute(statement, parameters)\n', 'suggestions': ['Verify database connection settings', 'Check for invalid queries or constraints', 'Ensure all required fields are provided']}
[2025-04-15 18:07:31] [INFO] 172.31.128.46 - - [15/Apr/2025 18:07:31] "GET /welcome HTTP/1.1" 0 -
[2025-04-15 18:07:31,328] [ERROR] Unhandled Exception: {'error_type': 'Database Error', 'error_message': "(psycopg2.errors.UndefinedColumn) column site.pixi_content does not exist\nLINE 1: ...tent, site.python_content AS site_python_content, site.pixi_...\n                                                             ^\n\n[SQL: SELECT site.id AS site_id, site.name AS site_name, site.slug AS site_slug, site.site_type AS site_site_type, site.html_content AS site_html_content, site.python_content AS site_python_content, site.pixi_content AS site_pixi_content, site.is_public AS site_is_public, site.created_at AS site_created_at, site.updated_at AS site_updated_at, site.user_id AS site_user_id, site.view_count AS site_view_count, site.analytics_enabled AS site_analytics_enabled \nFROM site \nWHERE site.user_id = %(user_id_1)s ORDER BY site.updated_at DESC]\n[parameters: {'user_id_1': 149}]\n(Background on this error at: https://sqlalche.me/e/20/f405)", 'error_details': None, 'file_name': None, 'line_number': None, 'code_snippet': None, 'traceback': '  File "/home/runner/workspace/.pythonlibs/lib/python3.11/site-packages/flask/app.py", line 867, in full_dispatch_request\n    rv = self.dispatch_request()\n         ^^^^^^^^^^^^^^^^^^^^^^^\n  File "/home/runner/workspace/.pythonlibs/lib/python3.11/site-packages/flask/app.py", line 852, in dispatch_request\n    return self.ensure_sync(self.view_functions[rule.endpoint])(**view_args)\n           ^^^^^^^^^^^^^^^^^^^^^^^^^^^^^^^^^^^^^^^^^^^^^^^^^^^^^^^^^^^^^^^^^\n  File "/home/runner/workspace/.pythonlibs/lib/python3.11/site-packages/flask_login/utils.py", line 290, in decorated_view\n    return current_app.ensure_sync(func)(*args, **kwargs)\n           ^^^^^^^^^^^^^^^^^^^^^^^^^^^^^^^^^^^^^^^^^^^^^^\n  File "/home/runner/workspace/app.py", line 598, in welcome\n    Site.updated_at.desc()).all()\n                            ^^^^^\n  File "/home/runner/workspace/.pythonlibs/lib/python3.11/site-packages/sqlalchemy/orm/query.py", line 2704, in all\n    return self._iter().all()  # type: ignore\n           ^^^^^^^^^^^^\n  File "/home/runner/workspace/.pythonlibs/lib/python3.11/site-packages/sqlalchemy/orm/query.py", line 2858, in _iter\n    result: Union[ScalarResult[_T], Result[_T]] = self.session.execute(\n                                                  ^^^^^^^^^^^^^^^^^^^^^\n  File "/home/runner/workspace/.pythonlibs/lib/python3.11/site-packages/sqlalchemy/orm/session.py", line 2365, in execute\n    return self._execute_internal(\n           ^^^^^^^^^^^^^^^^^^^^^^^\n  File "/home/runner/workspace/.pythonlibs/lib/python3.11/site-packages/sqlalchemy/orm/session.py", line 2251, in _execute_internal\n    result: Result[Any] = compile_state_cls.orm_execute_statement(\n                          ^^^^^^^^^^^^^^^^^^^^^^^^^^^^^^^^^^^^^^^^\n  File "/home/runner/workspace/.pythonlibs/lib/python3.11/site-packages/sqlalchemy/orm/context.py", line 306, in orm_execute_statement\n    result = conn.execute(\n             ^^^^^^^^^^^^^\n  File "/home/runner/workspace/.pythonlibs/lib/python3.11/site-packages/sqlalchemy/engine/base.py", line 1416, in execute\n    return meth(\n           ^^^^^\n  File "/home/runner/workspace/.pythonlibs/lib/python3.11/site-packages/sqlalchemy/sql/elements.py", line 523, in _execute_on_connection\n    return connection._execute_clauseelement(\n           ^^^^^^^^^^^^^^^^^^^^^^^^^^^^^^^^^^\n  File "/home/runner/workspace/.pythonlibs/lib/python3.11/site-packages/sqlalchemy/engine/base.py", line 1638, in _execute_clauseelement\n    ret = self._execute_context(\n          ^^^^^^^^^^^^^^^^^^^^^^\n  File "/home/runner/workspace/.pythonlibs/lib/python3.11/site-packages/sqlalchemy/engine/base.py", line 1843, in _execute_context\n    return self._exec_single_context(\n           ^^^^^^^^^^^^^^^^^^^^^^^^^^\n  File "/home/runner/workspace/.pythonlibs/lib/python3.11/site-packages/sqlalchemy/engine/base.py", line 1983, in _exec_single_context\n    self._handle_dbapi_exception(\n  File "/home/runner/workspace/.pythonlibs/lib/python3.11/site-packages/sqlalchemy/engine/base.py", line 2352, in _handle_dbapi_exception\n    raise sqlalchemy_exception.with_traceback(exc_info[2]) from e\n  File "/home/runner/workspace/.pythonlibs/lib/python3.11/site-packages/sqlalchemy/engine/base.py", line 1964, in _exec_single_context\n    self.dialect.do_execute(\n  File "/home/runner/workspace/.pythonlibs/lib/python3.11/site-packages/sqlalchemy/engine/default.py", line 945, in do_execute\n    cursor.execute(statement, parameters)\n', 'suggestions': ['Verify database connection settings', 'Check for invalid queries or constraints', 'Ensure all required fields are provided']}
[2025-04-15 18:07:31] [ERROR] Unhandled Exception: {'error_type': 'Database Error', 'error_message': "(psycopg2.errors.UndefinedColumn) column site.pixi_content does not exist\nLINE 1: ...tent, site.python_content AS site_python_content, site.pixi_...\n                                                             ^\n\n[SQL: SELECT site.id AS site_id, site.name AS site_name, site.slug AS site_slug, site.site_type AS site_site_type, site.html_content AS site_html_content, site.python_content AS site_python_content, site.pixi_content AS site_pixi_content, site.is_public AS site_is_public, site.created_at AS site_created_at, site.updated_at AS site_updated_at, site.user_id AS site_user_id, site.view_count AS site_view_count, site.analytics_enabled AS site_analytics_enabled \nFROM site \nWHERE site.user_id = %(user_id_1)s ORDER BY site.updated_at DESC]\n[parameters: {'user_id_1': 149}]\n(Background on this error at: https://sqlalche.me/e/20/f405)", 'error_details': None, 'file_name': None, 'line_number': None, 'code_snippet': None, 'traceback': '  File "/home/runner/workspace/.pythonlibs/lib/python3.11/site-packages/flask/app.py", line 867, in full_dispatch_request\n    rv = self.dispatch_request()\n         ^^^^^^^^^^^^^^^^^^^^^^^\n  File "/home/runner/workspace/.pythonlibs/lib/python3.11/site-packages/flask/app.py", line 852, in dispatch_request\n    return self.ensure_sync(self.view_functions[rule.endpoint])(**view_args)\n           ^^^^^^^^^^^^^^^^^^^^^^^^^^^^^^^^^^^^^^^^^^^^^^^^^^^^^^^^^^^^^^^^^\n  File "/home/runner/workspace/.pythonlibs/lib/python3.11/site-packages/flask_login/utils.py", line 290, in decorated_view\n    return current_app.ensure_sync(func)(*args, **kwargs)\n           ^^^^^^^^^^^^^^^^^^^^^^^^^^^^^^^^^^^^^^^^^^^^^^\n  File "/home/runner/workspace/app.py", line 598, in welcome\n    Site.updated_at.desc()).all()\n                            ^^^^^\n  File "/home/runner/workspace/.pythonlibs/lib/python3.11/site-packages/sqlalchemy/orm/query.py", line 2704, in all\n    return self._iter().all()  # type: ignore\n           ^^^^^^^^^^^^\n  File "/home/runner/workspace/.pythonlibs/lib/python3.11/site-packages/sqlalchemy/orm/query.py", line 2858, in _iter\n    result: Union[ScalarResult[_T], Result[_T]] = self.session.execute(\n                                                  ^^^^^^^^^^^^^^^^^^^^^\n  File "/home/runner/workspace/.pythonlibs/lib/python3.11/site-packages/sqlalchemy/orm/session.py", line 2365, in execute\n    return self._execute_internal(\n           ^^^^^^^^^^^^^^^^^^^^^^^\n  File "/home/runner/workspace/.pythonlibs/lib/python3.11/site-packages/sqlalchemy/orm/session.py", line 2251, in _execute_internal\n    result: Result[Any] = compile_state_cls.orm_execute_statement(\n                          ^^^^^^^^^^^^^^^^^^^^^^^^^^^^^^^^^^^^^^^^\n  File "/home/runner/workspace/.pythonlibs/lib/python3.11/site-packages/sqlalchemy/orm/context.py", line 306, in orm_execute_statement\n    result = conn.execute(\n             ^^^^^^^^^^^^^\n  File "/home/runner/workspace/.pythonlibs/lib/python3.11/site-packages/sqlalchemy/engine/base.py", line 1416, in execute\n    return meth(\n           ^^^^^\n  File "/home/runner/workspace/.pythonlibs/lib/python3.11/site-packages/sqlalchemy/sql/elements.py", line 523, in _execute_on_connection\n    return connection._execute_clauseelement(\n           ^^^^^^^^^^^^^^^^^^^^^^^^^^^^^^^^^^\n  File "/home/runner/workspace/.pythonlibs/lib/python3.11/site-packages/sqlalchemy/engine/base.py", line 1638, in _execute_clauseelement\n    ret = self._execute_context(\n          ^^^^^^^^^^^^^^^^^^^^^^\n  File "/home/runner/workspace/.pythonlibs/lib/python3.11/site-packages/sqlalchemy/engine/base.py", line 1843, in _execute_context\n    return self._exec_single_context(\n           ^^^^^^^^^^^^^^^^^^^^^^^^^^\n  File "/home/runner/workspace/.pythonlibs/lib/python3.11/site-packages/sqlalchemy/engine/base.py", line 1983, in _exec_single_context\n    self._handle_dbapi_exception(\n  File "/home/runner/workspace/.pythonlibs/lib/python3.11/site-packages/sqlalchemy/engine/base.py", line 2352, in _handle_dbapi_exception\n    raise sqlalchemy_exception.with_traceback(exc_info[2]) from e\n  File "/home/runner/workspace/.pythonlibs/lib/python3.11/site-packages/sqlalchemy/engine/base.py", line 1964, in _exec_single_context\n    self.dialect.do_execute(\n  File "/home/runner/workspace/.pythonlibs/lib/python3.11/site-packages/sqlalchemy/engine/default.py", line 945, in do_execute\n    cursor.execute(statement, parameters)\n', 'suggestions': ['Verify database connection settings', 'Check for invalid queries or constraints', 'Ensure all required fields are provided']}
[2025-04-15 18:07:31] [INFO] 172.31.128.46 - - [15/Apr/2025 18:07:31] "GET /welcome HTTP/1.1" 0 -